Workbook

Sheet REHBER
B1: TCF ARTİSTİK CİMNASTİK — KAPSAMLI OFFLİNE PUAN SİSTEMİ v2
B2: D + E − ND = Final · Takım Sıralaması · Alet Finalleri · Çıkış Sırası
B4: 📌 | C4: GENEL KULLANIM
B5: 1. | C5: YARIŞMA BİLGİLERİ sekmesine gidin → yarışma adı, tarih ve şehri doldurun.
B6: 2. | C6: Kategori sekmelerinde (MİNİK A KIZLAR vb.) sporcu Ad/Soyad/Okul/Tür girin.
B7: 3. | C7: Her alet için D, E, ND (Tarafsız Kesinti) puanlarını girin:
C8: • Final = MAX(0 , D + E − ND) → otomatik hesaplanır (mavi sütun).
C9: • Sadece Final puanı girecekseniz: D=0, E=final_puan, ND=0 kullanın.
B10: 4. | C10: Durum sütununa: N = Normal | G = Gecersiz | D = Yarışmadı/DNS
C11: G veya D girilirse o alet Final puanı otomatik 0 yapılır.
B12: 5. | C12: TOPLAM ve SIRALAMA otomatik hesaplanır. Eşit puanlılar aynı sırayı alır.
B13: 6. | C13: Her aletin kendi sıralama sütunu da vardır (alet bazlı final seçimi için).
B15: 🏆 | C15: TAKIM SIRALAMASI sekmesi
B16: • | C16: Her kategoride takım adını A sütununa manuel girin.
B17: • | C17: Her aletin "En İyi 3" değeri, ilgili kategori sayfasından otomatik çekilir.
B18: • | C18: SUMPRODUCT formülü kullanılır. Excel 2019+'ta otomatik çalışır.
B19: • | C19: Eski Excel (2016) kullanıyorsanız formül hücrelerini Ctrl+Shift+Enter ile onaylayın.
B20: • | C20: Takım Kesintisi (ceza) sütununa manuel girin → Final takım puanı otomatik güncellenir.
B22: 🎯 | C22: ALET FİNALLERİ sekmesi
B23: • | C23: Eleme sonucuna göre her alette en iyi 8 sporcu finals için el ile girilir.
B24: • | C24: Final turu için ayrı D/E/ND puanları girilir → Final puanı yeniden hesaplanır.
B25: • | C25: Final sıralaması yalnızca bu tur puanına göre otomatik hesaplanır.
... B43: 👦 | C43: GENÇ ERKEKLER: Yer (FX) + Kulplu Beygir (PH) + Halka (SR) + Atlama (VT) + Paralel (PB) + Barfiks (HB)

Sheet YARIŞMA BİLGİLERİ
B1: YARIŞMA BİLGİLERİ
B3: Yarışma Adı | C3: Buraya yarışma adını yazın
B4: Tarih | C4: GG.AA.YYYY
B5: Şehir / İl
B6: Düzenleyen Kurum
B7: Hakem Başkanı

Sheet MİNİK A KIZLAR
A1: MİNİK A KIZLAR
A2: ='YARIŞMA BİLGİLERİ'!C3&" — "&'YARIŞMA BİLGİLERİ'!C4&" | "&'YARIŞMA BİLGİLERİ'!C5
F3: ATLAMA (VT) | K3: SERBEST (FX) | R3: ALET SIRALARI (Eleme Seçimi için)
A4: No | B4: Ad | C4: Soyad | D4: Okul / Kulüp | E4: Tür | F4: D | G4: E | H4: ND | I4: Final | J4: Dur | K4: D | L4: E | M4: ND | N4: Final | O4: Dur | P4: TOPLAM | Q4: SIRALAMA | R4: VT | S4: FX
A5: Final = MAX(0, D+E−ND) | Dur: N=Normal · G=Gecersiz · D=Yarışmadı/DNS | Mavi sütun = formül (elle girme) | Yeşil = Toplam | Sarı = Sıralama
A6: 1 | I6: =IF(OR(J6="G",J6="D"),0,IF(AND(F6="",G6=""),0,MAX(0,IFERROR(F6+0,0)+IFERROR(G6+0,0)-IFERROR(H6+0,0)))) | N6: =IF(OR(O6="G",O6="D"),0,IF(AND(K6="",L6=""),0,MAX(0,IFERROR(K6+0,0)+IFERROR(L6+0,0)-IFERROR(M6+0,0)))) | P6: =IF(B6="","",IF(OR(J6="G",J6="D"),0,I6)+IF(OR(O6="G",O6="D"),0,N6)) | Q6: =IF(OR(B6="",P6=0),"-",RANK.EQ(P6,$P$6:$P$45,0)) | R6: =IF(OR(B6="",I6=0),"-",IF(OR(J6="G",J6="D"),IF(J6="G","G","D"),COUNTIF($I$6:$I$45,">"&I6)+1)) | S6: =IF(OR(B6="",N6=0),"-",IF(OR(O6="G",O6="D"),IF(O6="G","G","D"),COUNTIF($N$6:$N$45,">"&N6)+1))
A7: 2 | I7: =IF(OR(J7="G",J7="D"),0,IF(AND(F7="",G7=""),0,MAX(0,IFERROR(F7+0,0)+IFERROR(G7+0,0)-IFERROR(H7+0,0)))) | N7: =IF(OR(O7="G",O7="D"),0,IF(AND(K7="",L7=""),0,MAX(0,IFERROR(K7+0,0)+IFERROR(L7+0,0)-IFERROR(M7+0,0)))) | P7: =IF(B7="","",IF(OR(J7="G",J7="D"),0,I7)+IF(OR(O7="G",O7="D"),0,N7)) | Q7: =IF(OR(B7="",P7=0),"-",RANK.EQ(P7,$P$6:$P$45,0)) | R7: =IF(OR(B7="",I7=0),"-",IF(OR(J7="G",J7="D"),IF(J7="G","G","D"),COUNTIF($I$6:$I$45,">"&I7)+1)) | S7: =IF(OR(B7="",N7=0),"-",IF(OR(O7="G",O7="D"),IF(O7="G","G","D"),COUNTIF($N$6:$N$45,">"&N7)+1))
A8: 3 | I8: =IF(OR(J8="G",J8="D"),0,IF(AND(F8="",G8=""),0,MAX(0,IFERROR(F8+0,0)+IFERROR(G8+0,0)-IFERROR(H8+0,0)))) | N8: =IF(OR(O8="G",O8="D"),0,IF(AND(K8="",L8=""),0,MAX(0,IFERROR(K8+0,0)+IFERROR(L8+0,0)-IFERROR(M8+0,0)))) | P8: =IF(B8="","",IF(OR(J8="G",J8="D"),0,I8)+IF(OR(O8="G",O8="D"),0,N8)) | Q8: =IF(OR(B8="",P8=0),"-",RANK.EQ(P8,$P$6:$P$45,0)) | R8: =IF(OR(B8="",I8=0),"-",IF(OR(J8="G",J8="D"),IF(J8="G","G","D"),COUNTIF($I$6:$I$45,">"&I8)+1)) | S8: =IF(OR(B8="",N8=0),"-",IF(OR(O8="G",O8="D"),IF(O8="G","G","D"),COUNTIF($N$6:$N$45,">"&N8)+1))
A9: 4 | I9: =IF(OR(J9="G",J9="D"),0,IF(AND(F9="",G9=""),0,MAX(0,IFERROR(F9+0,0)+IFERROR(G9+0,0)-IFERROR(H9+0,0)))) | N9: =IF(OR(O9="G",O9="D"),0,IF(AND(K9="",L9=""),0,MAX(0,IFERROR(K9+0,0)+IFERROR(L9+0,0)-IFERROR(M9+0,0)))) | P9: =IF(B9="","",IF(OR(J9="G",J9="D"),0,I9)+IF(OR(O9="G",O9="D"),0,N9)) | Q9: =IF(OR(B9="",P9=0),"-",RANK.EQ(P9,$P$6:$P$45,0)) | R9: =IF(OR(B9="",I9=0),"-",IF(OR(J9="G",J9="D"),IF(J9="G","G","D"),COUNTIF($I$6:$I$45,">"&I9)+1)) | S9: =IF(OR(B9="",N9=0),"-",IF(OR(O9="G",O9="D"),IF(O9="G","G","D"),COUNTIF($N$6:$N$45,">"&N9)+1))
A10: 5 | I10: =IF(OR(J10="G",J10="D"),0,IF(AND(F10="",G10=""),0,MAX(0,IFERROR(F10+0,0)+IFERROR(G10+0,0)-IFERROR(H10+0,0)))) | N10: =IF(OR(O10="G",O10="D"),0,IF(AND(K10="",L10=""),0,MAX(0,IFERROR(K10+0,0)+IFERROR(L10+0,0)-IFERROR(M10+0,0)))) | P10: =IF(B10="","",IF(OR(J10="G",J10="D"),0,I10)+IF(OR(O10="G",O10="D"),0,N10)) | Q10: =IF(OR(B10="",P10=0),"-",RANK.EQ(P10,$P$6:$P$45,0)) | R10: =IF(OR(B10="",I10=0),"-",IF(OR(J10="G",J10="D"),IF(J10="G","G","D"),COUNTIF($I$6:$I$45,">"&I10)+1)) | S10: =IF(OR(B10="",N10=0),"-",IF(OR(O10="G",O10="D"),IF(O10="G","G","D"),COUNTIF($N$6:$N$45,">"&N10)+1))
A11: 6 | I11: =IF(OR(J11="G",J11="D"),0,IF(AND(F11="",G11=""),0,MAX(0,IFERROR(F11+0,0)+IFERROR(G11+0,0)-IFERROR(H11+0,0)))) | N11: =IF(OR(O11="G",O11="D"),0,IF(AND(K11="",L11=""),0,MAX(0,IFERROR(K11+0,0)+IFERROR(L11+0,0)-IFERROR(M11+0,0)))) | P11: =IF(B11="","",IF(OR(J11="G",J11="D"),0,I11)+IF(OR(O11="G",O11="D"),0,N11)) | Q11: =IF(OR(B11="",P11=0),"-",RANK.EQ(P11,$P$6:$P$45,0)) | R11: =IF(OR(B11="",I11=0),"-",IF(OR(J11="G",J11="D"),IF(J11="G","G","D"),COUNTIF($I$6:$I$45,">"&I11)+1)) | S11: =IF(OR(B11="",N11=0),"-",IF(OR(O11="G",O11="D"),IF(O11="G","G","D"),COUNTIF($N$6:$N$45,">"&N11)+1))
A12: 7 | I12: =IF(OR(J12="G",J12="D"),0,IF(AND(F12="",G12=""),0,MAX(0,IFERROR(F12+0,0)+IFERROR(G12+0,0)-IFERROR(H12+0,0)))) | N12: =IF(OR(O12="G",O12="D"),0,IF(AND(K12="",L12=""),0,MAX(0,IFERROR(K12+0,0)+IFERROR(L12+0,0)-IFERROR(M12+0,0)))) | P12: =IF(B12="","",IF(OR(J12="G",J12="D"),0,I12)+IF(OR(O12="G",O12="D"),0,N12)) | Q12: =IF(OR(B12="",P12=0),"-",RANK.EQ(P12,$P$6:$P$45,0)) | R12: =IF(OR(B12="",I12=0),"-",IF(OR(J12="G",J12="D"),IF(J12="G","G","D"),COUNTIF($I$6:$I$45,">"&I12)+1)) | S12: =IF(OR(B12="",N12=0),"-",IF(OR(O12="G",O12="D"),IF(O12="G","G","D"),COUNTIF($N$6:$N$45,">"&N12)+1))
A13: 8 | I13: =IF(OR(J13="G",J13="D"),0,IF(AND(F13="",G13=""),0,MAX(0,IFERROR(F13+0,0)+IFERROR(G13+0,0)-IFERROR(H13+0,0)))) | N13: =IF(OR(O13="G",O13="D"),0,IF(AND(K13="",L13=""),0,MAX(0,IFERROR(K13+0,0)+IFERROR(L13+0,0)-IFERROR(M13+0,0)))) | P13: =IF(B13="","",IF(OR(J13="G",J13="D"),0,I13)+IF(OR(O13="G",O13="D"),0,N13)) | Q13: =IF(OR(B13="",P13=0),"-",RANK.EQ(P13,$P$6:$P$45,0)) | R13: =IF(OR(B13="",I13=0),"-",IF(OR(J13="G",J13="D"),IF(J13="G","G","D"),COUNTIF($I$6:$I$45,">"&I13)+1)) | S13: =IF(OR(B13="",N13=0),"-",IF(OR(O13="G",O13="D"),IF(O13="G","G","D"),COUNTIF($N$6:$N$45,">"&N13)+1))
A14: 9 | I14: =IF(OR(J14="G",J14="D"),0,IF(AND(F14="",G14=""),0,MAX(0,IFERROR(F14+0,0)+IFERROR(G14+0,0)-IFERROR(H14+0,0)))) | N14: =IF(OR(O14="G",O14="D"),0,IF(AND(K14="",L14=""),0,MAX(0,IFERROR(K14+0,0)+IFERROR(L14+0,0)-IFERROR(M14+0,0)))) | P14: =IF(B14="","",IF(OR(J14="G",J14="D"),0,I14)+IF(OR(O14="G",O14="D"),0,N14)) | Q14: =IF(OR(B14="",P14=0),"-",RANK.EQ(P14,$P$6:$P$45,0)) | R14: =IF(OR(B14="",I14=0),"-",IF(OR(J14="G",J14="D"),IF(J14="G","G","D"),COUNTIF($I$6:$I$45,">"&I14)+1)) | S14: =IF(OR(B14="",N14=0),"-",IF(OR(O14="G",O14="D"),IF(O14="G","G","D"),COUNTIF($N$6:$N$45,">"&N14)+1))
A15: 10 | I15: =IF(OR(J15="G",J15="D"),0,IF(AND(F15="",G15=""),0,MAX(0,IFERROR(F15+0,0)+IFERROR(G15+0,0)-IFERROR(H15+0,0)))) | N15: =IF(OR(O15="G",O15="D"),0,IF(AND(K15="",L15=""),0,MAX(0,IFERROR(K15+0,0)+IFERROR(L15+0,0)-IFERROR(M15+0,0)))) | P15: =IF(B15="","",IF(OR(J15="G",J15="D"),0,I15)+IF(OR(O15="G",O15="D"),0,N15)) | Q15: =IF(OR(B15="",P15=0),"-",RANK.EQ(P15,$P$6:$P$45,0)) | R15: =IF(OR(B15="",I15=0),"-",IF(OR(J15="G",J15="D"),IF(J15="G","G","D"),COUNTIF($I$6:$I$45,">"&I15)+1)) | S15: =IF(OR(B15="",N15=0),"-",IF(OR(O15="G",O15="D"),IF(O15="G","G","D"),COUNTIF($N$6:$N$45,">"&N15)+1))
A16: 11 | I16: =IF(OR(J16="G",J16="D"),0,IF(AND(F16="",G16=""),0,MAX(0,IFERROR(F16+0,0)+IFERROR(G16+0,0)-IFERROR(H16+0,0)))) | N16: =IF(OR(O16="G",O16="D"),0,IF(AND(K16="",L16=""),0,MAX(0,IFERROR(K16+0,0)+IFERROR(L16+0,0)-IFERROR(M16+0,0)))) | P16: =IF(B16="","",IF(OR(J16="G",J16="D"),0,I16)+IF(OR(O16="G",O16="D"),0,N16)) | Q16: =IF(OR(B16="",P16=0),"-",RANK.EQ(P16,$P$6:$P$45,0)) | R16: =IF(OR(B16="",I16=0),"-",IF(OR(J16="G",J16="D"),IF(J16="G","G","D"),COUNTIF($I$6:$I$45,">"&I16)+1)) | S16: =IF(OR(B16="",N16=0),"-",IF(OR(O16="G",O16="D"),IF(O16="G","G","D"),COUNTIF($N$6:$N$45,">"&N16)+1))
A17: 12 | I17: =IF(OR(J17="G",J17="D"),0,IF(AND(F17="",G17=""),0,MAX(0,IFERROR(F17+0,0)+IFERROR(G17+0,0)-IFERROR(H17+0,0)))) | N17: =IF(OR(O17="G",O17="D"),0,IF(AND(K17="",L17=""),0,MAX(0,IFERROR(K17+0,0)+IFERROR(L17+0,0)-IFERROR(M17+0,0)))) | P17: =IF(B17="","",IF(OR(J17="G",J17="D"),0,I17)+IF(OR(O17="G",O17="D"),0,N17)) | Q17: =IF(OR(B17="",P17=0),"-",RANK.EQ(P17,$P$6:$P$45,0)) | R17: =IF(OR(B17="",I17=0),"-",IF(OR(J17="G",J17="D"),IF(J17="G","G","D"),COUNTIF($I$6:$I$45,">"&I17)+1)) | S17: =IF(OR(B17="",N17=0),"-",IF(OR(O17="G",O17="D"),IF(O17="G","G","D"),COUNTIF($N$6:$N$45,">"&N17)+1))
... A45: 40 | I45: =IF(OR(J45="G",J45="D"),0,IF(AND(F45="",G45=""),0,MAX(0,IFERROR(F45+0,0)+IFERROR(G45+0,0)-IFERROR(H45+0,0)))) | N45: =IF(OR(O45="G",O45="D"),0,IF(AND(K45="",L45=""),0,MAX(0,IFERROR(K45+0,0)+IFERROR(L45+0,0)-IFERROR(M45+0,0)))) | P45: =IF(B45="","",IF(OR(J45="G",J45="D"),0,I45)+IF(OR(O45="G",O45="D"),0,N45)) | Q45: =IF(OR(B45="",P45=0),"-",RANK.EQ(P45,$P$6:$P$45,0)) | R45: =IF(OR(B45="",I45=0),"-",IF(OR(J45="G",J45="D"),IF(J45="G","G","D"),COUNTIF($I$6:$I$45,">"&I45)+1)) | S45: =IF(OR(B45="",N45=0),"-",IF(OR(O45="G",O45="D"),IF(O45="G","G","D"),COUNTIF($N$6:$N$45,">"&N45)+1))
A47: =COUNTA(B6:B45)&" sporcu kayıtlı"

Sheet MİNİK A ERKEKLER
A1: MİNİK A ERKEKLER
A2: ='YARIŞMA BİLGİLERİ'!C3&" — "&'YARIŞMA BİLGİLERİ'!C4&" | "&'YARIŞMA BİLGİLERİ'!C5
F3: YER (FX) | K3: ATLAMA (VT) | R3: ALET SIRALARI (Eleme Seçimi için)
A4: No | B4: Ad | C4: Soyad | D4: Okul / Kulüp | E4: Tür | F4: D | G4: E | H4: ND | I4: Final | J4: Dur | K4: D | L4: E | M4: ND | N4: Final | O4: Dur | P4: TOPLAM | Q4: SIRALAMA | R4: FX | S4: VT
A5: Final = MAX(0, D+E−ND) | Dur: N=Normal · G=Gecersiz · D=Yarışmadı/DNS | Mavi sütun = formül (elle girme) | Yeşil = Toplam | Sarı = Sıralama
A6: 1 | I6: =IF(OR(J6="G",J6="D"),0,IF(AND(F6="",G6=""),0,MAX(0,IFERROR(F6+0,0)+IFERROR(G6+0,0)-IFERROR(H6+0,0)))) | N6: =IF(OR(O6="G",O6="D"),0,IF(AND(K6="",L6=""),0,MAX(0,IFERROR(K6+0,0)+IFERROR(L6+0,0)-IFERROR(M6+0,0)))) | P6: =IF(B6="","",IF(OR(J6="G",J6="D"),0,I6)+IF(OR(O6="G",O6="D"),0,N6)) | Q6: =IF(OR(B6="",P6=0),"-",RANK.EQ(P6,$P$6:$P$45,0)) | R6: =IF(OR(B6="",I6=0),"-",IF(OR(J6="G",J6="D"),IF(J6="G","G","D"),COUNTIF($I$6:$I$45,">"&I6)+1)) | S6: =IF(OR(B6="",N6=0),"-",IF(OR(O6="G",O6="D"),IF(O6="G","G","D"),COUNTIF($N$6:$N$45,">"&N6)+1))
A7: 2 | I7: =IF(OR(J7="G",J7="D"),0,IF(AND(F7="",G7=""),0,MAX(0,IFERROR(F7+0,0)+IFERROR(G7+0,0)-IFERROR(H7+0,0)))) | N7: =IF(OR(O7="G",O7="D"),0,IF(AND(K7="",L7=""),0,MAX(0,IFERROR(K7+0,0)+IFERROR(L7+0,0)-IFERROR(M7+0,0)))) | P7: =IF(B7="","",IF(OR(J7="G",J7="D"),0,I7)+IF(OR(O7="G",O7="D"),0,N7)) | Q7: =IF(OR(B7="",P7=0),"-",RANK.EQ(P7,$P$6:$P$45,0)) | R7: =IF(OR(B7="",I7=0),"-",IF(OR(J7="G",J7="D"),IF(J7="G","G","D"),COUNTIF($I$6:$I$45,">"&I7)+1)) | S7: =IF(OR(B7="",N7=0),"-",IF(OR(O7="G",O7="D"),IF(O7="G","G","D"),COUNTIF($N$6:$N$45,">"&N7)+1))
A8: 3 | I8: =IF(OR(J8="G",J8="D"),0,IF(AND(F8="",G8=""),0,MAX(0,IFERROR(F8+0,0)+IFERROR(G8+0,0)-IFERROR(H8+0,0)))) | N8: =IF(OR(O8="G",O8="D"),0,IF(AND(K8="",L8=""),0,MAX(0,IFERROR(K8+0,0)+IFERROR(L8+0,0)-IFERROR(M8+0,0)))) | P8: =IF(B8="","",IF(OR(J8="G",J8="D"),0,I8)+IF(OR(O8="G",O8="D"),0,N8)) | Q8: =IF(OR(B8="",P8=0),"-",RANK.EQ(P8,$P$6:$P$45,0)) | R8: =IF(OR(B8="",I8=0),"-",IF(OR(J8="G",J8="D"),IF(J8="G","G","D"),COUNTIF($I$6:$I$45,">"&I8)+1)) | S8: =IF(OR(B8="",N8=0),"-",IF(OR(O8="G",O8="D"),IF(O8="G","G","D"),COUNTIF($N$6:$N$45,">"&N8)+1))
A9: 4 | I9: =IF(OR(J9="G",J9="D"),0,IF(AND(F9="",G9=""),0,MAX(0,IFERROR(F9+0,0)+IFERROR(G9+0,0)-IFERROR(H9+0,0)))) | N9: =IF(OR(O9="G",O9="D"),0,IF(AND(K9="",L9=""),0,MAX(0,IFERROR(K9+0,0)+IFERROR(L9+0,0)-IFERROR(M9+0,0)))) | P9: =IF(B9="","",IF(OR(J9="G",J9="D"),0,I9)+IF(OR(O9="G",O9="D"),0,N9)) | Q9: =IF(OR(B9="",P9=0),"-",RANK.EQ(P9,$P$6:$P$45,0)) | R9: =IF(OR(B9="",I9=0),"-",IF(OR(J9="G",J9="D"),IF(J9="G","G","D"),COUNTIF($I$6:$I$45,">"&I9)+1)) | S9: =IF(OR(B9="",N9=0),"-",IF(OR(O9="G",O9="D"),IF(O9="G","G","D"),COUNTIF($N$6:$N$45,">"&N9)+1))
A10: 5 | I10: =IF(OR(J10="G",J10="D"),0,IF(AND(F10="",G10=""),0,MAX(0,IFERROR(F10+0,0)+IFERROR(G10+0,0)-IFERROR(H10+0,0)))) | N10: =IF(OR(O10="G",O10="D"),0,IF(AND(K10="",L10=""),0,MAX(0,IFERROR(K10+0,0)+IFERROR(L10+0,0)-IFERROR(M10+0,0)))) | P10: =IF(B10="","",IF(OR(J10="G",J10="D"),0,I10)+IF(OR(O10="G",O10="D"),0,N10)) | Q10: =IF(OR(B10="",P10=0),"-",RANK.EQ(P10,$P$6:$P$45,0)) | R10: =IF(OR(B10="",I10=0),"-",IF(OR(J10="G",J10="D"),IF(J10="G","G","D"),COUNTIF($I$6:$I$45,">"&I10)+1)) | S10: =IF(OR(B10="",N10=0),"-",IF(OR(O10="G",O10="D"),IF(O10="G","G","D"),COUNTIF($N$6:$N$45,">"&N10)+1))
A11: 6 | I11: =IF(OR(J11="G",J11="D"),0,IF(AND(F11="",G11=""),0,MAX(0,IFERROR(F11+0,0)+IFERROR(G11+0,0)-IFERROR(H11+0,0)))) | N11: =IF(OR(O11="G",O11="D"),0,IF(AND(K11="",L11=""),0,MAX(0,IFERROR(K11+0,0)+IFERROR(L11+0,0)-IFERROR(M11+0,0)))) | P11: =IF(B11="","",IF(OR(J11="G",J11="D"),0,I11)+IF(OR(O11="G",O11="D"),0,N11)) | Q11: =IF(OR(B11="",P11=0),"-",RANK.EQ(P11,$P$6:$P$45,0)) | R11: =IF(OR(B11="",I11=0),"-",IF(OR(J11="G",J11="D"),IF(J11="G","G","D"),COUNTIF($I$6:$I$45,">"&I11)+1)) | S11: =IF(OR(B11="",N11=0),"-",IF(OR(O11="G",O11="D"),IF(O11="G","G","D"),COUNTIF($N$6:$N$45,">"&N11)+1))
A12: 7 | I12: =IF(OR(J12="G",J12="D"),0,IF(AND(F12="",G12=""),0,MAX(0,IFERROR(F12+0,0)+IFERROR(G12+0,0)-IFERROR(H12+0,0)))) | N12: =IF(OR(O12="G",O12="D"),0,IF(AND(K12="",L12=""),0,MAX(0,IFERROR(K12+0,0)+IFERROR(L12+0,0)-IFERROR(M12+0,0)))) | P12: =IF(B12="","",IF(OR(J12="G",J12="D"),0,I12)+IF(OR(O12="G",O12="D"),0,N12)) | Q12: =IF(OR(B12="",P12=0),"-",RANK.EQ(P12,$P$6:$P$45,0)) | R12: =IF(OR(B12="",I12=0),"-",IF(OR(J12="G",J12="D"),IF(J12="G","G","D"),COUNTIF($I$6:$I$45,">"&I12)+1)) | S12: =IF(OR(B12="",N12=0),"-",IF(OR(O12="G",O12="D"),IF(O12="G","G","D"),COUNTIF($N$6:$N$45,">"&N12)+1))
A13: 8 | I13: =IF(OR(J13="G",J13="D"),0,IF(AND(F13="",G13=""),0,MAX(0,IFERROR(F13+0,0)+IFERROR(G13+0,0)-IFERROR(H13+0,0)))) | N13: =IF(OR(O13="G",O13="D"),0,IF(AND(K13="",L13=""),0,MAX(0,IFERROR(K13+0,0)+IFERROR(L13+0,0)-IFERROR(M13+0,0)))) | P13: =IF(B13="","",IF(OR(J13="G",J13="D"),0,I13)+IF(OR(O13="G",O13="D"),0,N13)) | Q13: =IF(OR(B13="",P13=0),"-",RANK.EQ(P13,$P$6:$P$45,0)) | R13: =IF(OR(B13="",I13=0),"-",IF(OR(J13="G",J13="D"),IF(J13="G","G","D"),COUNTIF($I$6:$I$45,">"&I13)+1)) | S13: =IF(OR(B13="",N13=0),"-",IF(OR(O13="G",O13="D"),IF(O13="G","G","D"),COUNTIF($N$6:$N$45,">"&N13)+1))
A14: 9 | I14: =IF(OR(J14="G",J14="D"),0,IF(AND(F14="",G14=""),0,MAX(0,IFERROR(F14+0,0)+IFERROR(G14+0,0)-IFERROR(H14+0,0)))) | N14: =IF(OR(O14="G",O14="D"),0,IF(AND(K14="",L14=""),0,MAX(0,IFERROR(K14+0,0)+IFERROR(L14+0,0)-IFERROR(M14+0,0)))) | P14: =IF(B14="","",IF(OR(J14="G",J14="D"),0,I14)+IF(OR(O14="G",O14="D"),0,N14)) | Q14: =IF(OR(B14="",P14=0),"-",RANK.EQ(P14,$P$6:$P$45,0)) | R14: =IF(OR(B14="",I14=0),"-",IF(OR(J14="G",J14="D"),IF(J14="G","G","D"),COUNTIF($I$6:$I$45,">"&I14)+1)) | S14: =IF(OR(B14="",N14=0),"-",IF(OR(O14="G",O14="D"),IF(O14="G","G","D"),COUNTIF($N$6:$N$45,">"&N14)+1))
A15: 10 | I15: =IF(OR(J15="G",J15="D"),0,IF(AND(F15="",G15=""),0,MAX(0,IFERROR(F15+0,0)+IFERROR(G15+0,0)-IFERROR(H15+0,0)))) | N15: =IF(OR(O15="G",O15="D"),0,IF(AND(K15="",L15=""),0,MAX(0,IFERROR(K15+0,0)+IFERROR(L15+0,0)-IFERROR(M15+0,0)))) | P15: =IF(B15="","",IF(OR(J15="G",J15="D"),0,I15)+IF(OR(O15="G",O15="D"),0,N15)) | Q15: =IF(OR(B15="",P15=0),"-",RANK.EQ(P15,$P$6:$P$45,0)) | R15: =IF(OR(B15="",I15=0),"-",IF(OR(J15="G",J15="D"),IF(J15="G","G","D"),COUNTIF($I$6:$I$45,">"&I15)+1)) | S15: =IF(OR(B15="",N15=0),"-",IF(OR(O15="G",O15="D"),IF(O15="G","G","D"),COUNTIF($N$6:$N$45,">"&N15)+1))
A16: 11 | I16: =IF(OR(J16="G",J16="D"),0,IF(AND(F16="",G16=""),0,MAX(0,IFERROR(F16+0,0)+IFERROR(G16+0,0)-IFERROR(H16+0,0)))) | N16: =IF(OR(O16="G",O16="D"),0,IF(AND(K16="",L16=""),0,MAX(0,IFERROR(K16+0,0)+IFERROR(L16+0,0)-IFERROR(M16+0,0)))) | P16: =IF(B16="","",IF(OR(J16="G",J16="D"),0,I16)+IF(OR(O16="G",O16="D"),0,N16)) | Q16: =IF(OR(B16="",P16=0),"-",RANK.EQ(P16,$P$6:$P$45,0)) | R16: =IF(OR(B16="",I16=0),"-",IF(OR(J16="G",J16="D"),IF(J16="G","G","D"),COUNTIF($I$6:$I$45,">"&I16)+1)) | S16: =IF(OR(B16="",N16=0),"-",IF(OR(O16="G",O16="D"),IF(O16="G","G","D"),COUNTIF($N$6:$N$45,">"&N16)+1))
A17: 12 | I17: =IF(OR(J17="G",J17="D"),0,IF(AND(F17="",G17=""),0,MAX(0,IFERROR(F17+0,0)+IFERROR(G17+0,0)-IFERROR(H17+0,0)))) | N17: =IF(OR(O17="G",O17="D"),0,IF(AND(K17="",L17=""),0,MAX(0,IFERROR(K17+0,0)+IFERROR(L17+0,0)-IFERROR(M17+0,0)))) | P17: =IF(B17="","",IF(OR(J17="G",J17="D"),0,I17)+IF(OR(O17="G",O17="D"),0,N17)) | Q17: =IF(OR(B17="",P17=0),"-",RANK.EQ(P17,$P$6:$P$45,0)) | R17: =IF(OR(B17="",I17=0),"-",IF(OR(J17="G",J17="D"),IF(J17="G","G","D"),COUNTIF($I$6:$I$45,">"&I17)+1)) | S17: =IF(OR(B17="",N17=0),"-",IF(OR(O17="G",O17="D"),IF(O17="G","G","D"),COUNTIF($N$6:$N$45,">"&N17)+1))
... A45: 40 | I45: =IF(OR(J45="G",J45="D"),0,IF(AND(F45="",G45=""),0,MAX(0,IFERROR(F45+0,0)+IFERROR(G45+0,0)-IFERROR(H45+0,0)))) | N45: =IF(OR(O45="G",O45="D"),0,IF(AND(K45="",L45=""),0,MAX(0,IFERROR(K45+0,0)+IFERROR(L45+0,0)-IFERROR(M45+0,0)))) | P45: =IF(B45="","",IF(OR(J45="G",J45="D"),0,I45)+IF(OR(O45="G",O45="D"),0,N45)) | Q45: =IF(OR(B45="",P45=0),"-",RANK.EQ(P45,$P$6:$P$45,0)) | R45: =IF(OR(B45="",I45=0),"-",IF(OR(J45="G",J45="D"),IF(J45="G","G","D"),COUNTIF($I$6:$I$45,">"&I45)+1)) | S45: =IF(OR(B45="",N45=0),"-",IF(OR(O45="G",O45="D"),IF(O45="G","G","D"),COUNTIF($N$6:$N$45,">"&N45)+1))
A47: =COUNTA(B6:B45)&" sporcu kayıtlı"

Sheet MİNİK B KIZLAR
A1: MİNİK B KIZLAR
A2: ='YARIŞMA BİLGİLERİ'!C3&" — "&'YARIŞMA BİLGİLERİ'!C4&" | "&'YARIŞMA BİLGİLERİ'!C5
F3: ATLAMA (VT) | K3: SERBEST (FX) | R3: ALET SIRALARI (Eleme Seçimi için)
A4: No | B4: Ad | C4: Soyad | D4: Okul / Kulüp | E4: Tür | F4: D | G4: E | H4: ND | I4: Final | J4: Dur | K4: D | L4: E | M4: ND | N4: Final | O4: Dur | P4: TOPLAM | Q4: SIRALAMA | R4: VT | S4: FX
A5: Final = MAX(0, D+E−ND) | Dur: N=Normal · G=Gecersiz · D=Yarışmadı/DNS | Mavi sütun = formül (elle girme) | Yeşil = Toplam | Sarı = Sıralama
A6: 1 | I6: =IF(OR(J6="G",J6="D"),0,IF(AND(F6="",G6=""),0,MAX(0,IFERROR(F6+0,0)+IFERROR(G6+0,0)-IFERROR(H6+0,0)))) | N6: =IF(OR(O6="G",O6="D"),0,IF(AND(K6="",L6=""),0,MAX(0,IFERROR(K6+0,0)+IFERROR(L6+0,0)-IFERROR(M6+0,0)))) | P6: =IF(B6="","",IF(OR(J6="G",J6="D"),0,I6)+IF(OR(O6="G",O6="D"),0,N6)) | Q6: =IF(OR(B6="",P6=0),"-",RANK.EQ(P6,$P$6:$P$45,0)) | R6: =IF(OR(B6="",I6=0),"-",IF(OR(J6="G",J6="D"),IF(J6="G","G","D"),COUNTIF($I$6:$I$45,">"&I6)+1)) | S6: =IF(OR(B6="",N6=0),"-",IF(OR(O6="G",O6="D"),IF(O6="G","G","D"),COUNTIF($N$6:$N$45,">"&N6)+1))
A7: 2 | I7: =IF(OR(J7="G",J7="D"),0,IF(AND(F7="",G7=""),0,MAX(0,IFERROR(F7+0,0)+IFERROR(G7+0,0)-IFERROR(H7+0,0)))) | N7: =IF(OR(O7="G",O7="D"),0,IF(AND(K7="",L7=""),0,MAX(0,IFERROR(K7+0,0)+IFERROR(L7+0,0)-IFERROR(M7+0,0)))) | P7: =IF(B7="","",IF(OR(J7="G",J7="D"),0,I7)+IF(OR(O7="G",O7="D"),0,N7)) | Q7: =IF(OR(B7="",P7=0),"-",RANK.EQ(P7,$P$6:$P$45,0)) | R7: =IF(OR(B7="",I7=0),"-",IF(OR(J7="G",J7="D"),IF(J7="G","G","D"),COUNTIF($I$6:$I$45,">"&I7)+1)) | S7: =IF(OR(B7="",N7=0),"-",IF(OR(O7="G",O7="D"),IF(O7="G","G","D"),COUNTIF($N$6:$N$45,">"&N7)+1))
A8: 3 | I8: =IF(OR(J8="G",J8="D"),0,IF(AND(F8="",G8=""),0,MAX(0,IFERROR(F8+0,0)+IFERROR(G8+0,0)-IFERROR(H8+0,0)))) | N8: =IF(OR(O8="G",O8="D"),0,IF(AND(K8="",L8=""),0,MAX(0,IFERROR(K8+0,0)+IFERROR(L8+0,0)-IFERROR(M8+0,0)))) | P8: =IF(B8="","",IF(OR(J8="G",J8="D"),0,I8)+IF(OR(O8="G",O8="D"),0,N8)) | Q8: =IF(OR(B8="",P8=0),"-",RANK.EQ(P8,$P$6:$P$45,0)) | R8: =IF(OR(B8="",I8=0),"-",IF(OR(J8="G",J8="D"),IF(J8="G","G","D"),COUNTIF($I$6:$I$45,">"&I8)+1)) | S8: =IF(OR(B8="",N8=0),"-",IF(OR(O8="G",O8="D"),IF(O8="G","G","D"),COUNTIF($N$6:$N$45,">"&N8)+1))
A9: 4 | I9: =IF(OR(J9="G",J9="D"),0,IF(AND(F9="",G9=""),0,MAX(0,IFERROR(F9+0,0)+IFERROR(G9+0,0)-IFERROR(H9+0,0)))) | N9: =IF(OR(O9="G",O9="D"),0,IF(AND(K9="",L9=""),0,MAX(0,IFERROR(K9+0,0)+IFERROR(L9+0,0)-IFERROR(M9+0,0)))) | P9: =IF(B9="","",IF(OR(J9="G",J9="D"),0,I9)+IF(OR(O9="G",O9="D"),0,N9)) | Q9: =IF(OR(B9="",P9=0),"-",RANK.EQ(P9,$P$6:$P$45,0)) | R9: =IF(OR(B9="",I9=0),"-",IF(OR(J9="G",J9="D"),IF(J9="G","G","D"),COUNTIF($I$6:$I$45,">"&I9)+1)) | S9: =IF(OR(B9="",N9=0),"-",IF(OR(O9="G",O9="D"),IF(O9="G","G","D"),COUNTIF($N$6:$N$45,">"&N9)+1))
A10: 5 | I10: =IF(OR(J10="G",J10="D"),0,IF(AND(F10="",G10=""),0,MAX(0,IFERROR(F10+0,0)+IFERROR(G10+0,0)-IFERROR(H10+0,0)))) | N10: =IF(OR(O10="G",O10="D"),0,IF(AND(K10="",L10=""),0,MAX(0,IFERROR(K10+0,0)+IFERROR(L10+0,0)-IFERROR(M10+0,0)))) | P10: =IF(B10="","",IF(OR(J10="G",J10="D"),0,I10)+IF(OR(O10="G",O10="D"),0,N10)) | Q10: =IF(OR(B10="",P10=0),"-",RANK.EQ(P10,$P$6:$P$45,0)) | R10: =IF(OR(B10="",I10=0),"-",IF(OR(J10="G",J10="D"),IF(J10="G","G","D"),COUNTIF($I$6:$I$45,">"&I10)+1)) | S10: =IF(OR(B10="",N10=0),"-",IF(OR(O10="G",O10="D"),IF(O10="G","G","D"),COUNTIF($N$6:$N$45,">"&N10)+1))
A11: 6 | I11: =IF(OR(J11="G",J11="D"),0,IF(AND(F11="",G11=""),0,MAX(0,IFERROR(F11+0,0)+IFERROR(G11+0,0)-IFERROR(H11+0,0)))) | N11: =IF(OR(O11="G",O11="D"),0,IF(AND(K11="",L11=""),0,MAX(0,IFERROR(K11+0,0)+IFERROR(L11+0,0)-IFERROR(M11+0,0)))) | P11: =IF(B11="","",IF(OR(J11="G",J11="D"),0,I11)+IF(OR(O11="G",O11="D"),0,N11)) | Q11: =IF(OR(B11="",P11=0),"-",RANK.EQ(P11,$P$6:$P$45,0)) | R11: =IF(OR(B11="",I11=0),"-",IF(OR(J11="G",J11="D"),IF(J11="G","G","D"),COUNTIF($I$6:$I$45,">"&I11)+1)) | S11: =IF(OR(B11="",N11=0),"-",IF(OR(O11="G",O11="D"),IF(O11="G","G","D"),COUNTIF($N$6:$N$45,">"&N11)+1))
A12: 7 | I12: =IF(OR(J12="G",J12="D"),0,IF(AND(F12="",G12=""),0,MAX(0,IFERROR(F12+0,0)+IFERROR(G12+0,0)-IFERROR(H12+0,0)))) | N12: =IF(OR(O12="G",O12="D"),0,IF(AND(K12="",L12=""),0,MAX(0,IFERROR(K12+0,0)+IFERROR(L12+0,0)-IFERROR(M12+0,0)))) | P12: =IF(B12="","",IF(OR(J12="G",J12="D"),0,I12)+IF(OR(O12="G",O12="D"),0,N12)) | Q12: =IF(OR(B12="",P12=0),"-",RANK.EQ(P12,$P$6:$P$45,0)) | R12: =IF(OR(B12="",I12=0),"-",IF(OR(J12="G",J12="D"),IF(J12="G","G","D"),COUNTIF($I$6:$I$45,">"&I12)+1)) | S12: =IF(OR(B12="",N12=0),"-",IF(OR(O12="G",O12="D"),IF(O12="G","G","D"),COUNTIF($N$6:$N$45,">"&N12)+1))
A13: 8 | I13: =IF(OR(J13="G",J13="D"),0,IF(AND(F13="",G13=""),0,MAX(0,IFERROR(F13+0,0)+IFERROR(G13+0,0)-IFERROR(H13+0,0)))) | N13: =IF(OR(O13="G",O13="D"),0,IF(AND(K13="",L13=""),0,MAX(0,IFERROR(K13+0,0)+IFERROR(L13+0,0)-IFERROR(M13+0,0)))) | P13: =IF(B13="","",IF(OR(J13="G",J13="D"),0,I13)+IF(OR(O13="G",O13="D"),0,N13)) | Q13: =IF(OR(B13="",P13=0),"-",RANK.EQ(P13,$P$6:$P$45,0)) | R13: =IF(OR(B13="",I13=0),"-",IF(OR(J13="G",J13="D"),IF(J13="G","G","D"),COUNTIF($I$6:$I$45,">"&I13)+1)) | S13: =IF(OR(B13="",N13=0),"-",IF(OR(O13="G",O13="D"),IF(O13="G","G","D"),COUNTIF($N$6:$N$45,">"&N13)+1))
A14: 9 | I14: =IF(OR(J14="G",J14="D"),0,IF(AND(F14="",G14=""),0,MAX(0,IFERROR(F14+0,0)+IFERROR(G14+0,0)-IFERROR(H14+0,0)))) | N14: =IF(OR(O14="G",O14="D"),0,IF(AND(K14="",L14=""),0,MAX(0,IFERROR(K14+0,0)+IFERROR(L14+0,0)-IFERROR(M14+0,0)))) | P14: =IF(B14="","",IF(OR(J14="G",J14="D"),0,I14)+IF(OR(O14="G",O14="D"),0,N14)) | Q14: =IF(OR(B14="",P14=0),"-",RANK.EQ(P14,$P$6:$P$45,0)) | R14: =IF(OR(B14="",I14=0),"-",IF(OR(J14="G",J14="D"),IF(J14="G","G","D"),COUNTIF($I$6:$I$45,">"&I14)+1)) | S14: =IF(OR(B14="",N14=0),"-",IF(OR(O14="G",O14="D"),IF(O14="G","G","D"),COUNTIF($N$6:$N$45,">"&N14)+1))
A15: 10 | I15: =IF(OR(J15="G",J15="D"),0,IF(AND(F15="",G15=""),0,MAX(0,IFERROR(F15+0,0)+IFERROR(G15+0,0)-IFERROR(H15+0,0)))) | N15: =IF(OR(O15="G",O15="D"),0,IF(AND(K15="",L15=""),0,MAX(0,IFERROR(K15+0,0)+IFERROR(L15+0,0)-IFERROR(M15+0,0)))) | P15: =IF(B15="","",IF(OR(J15="G",J15="D"),0,I15)+IF(OR(O15="G",O15="D"),0,N15)) | Q15: =IF(OR(B15="",P15=0),"-",RANK.EQ(P15,$P$6:$P$45,0)) | R15: =IF(OR(B15="",I15=0),"-",IF(OR(J15="G",J15="D"),IF(J15="G","G","D"),COUNTIF($I$6:$I$45,">"&I15)+1)) | S15: =IF(OR(B15="",N15=0),"-",IF(OR(O15="G",O15="D"),IF(O15="G","G","D"),COUNTIF($N$6:$N$45,">"&N15)+1))
A16: 11 | I16: =IF(OR(J16="G",J16="D"),0,IF(AND(F16="",G16=""),0,MAX(0,IFERROR(F16+0,0)+IFERROR(G16+0,0)-IFERROR(H16+0,0)))) | N16: =IF(OR(O16="G",O16="D"),0,IF(AND(K16="",L16=""),0,MAX(0,IFERROR(K16+0,0)+IFERROR(L16+0,0)-IFERROR(M16+0,0)))) | P16: =IF(B16="","",IF(OR(J16="G",J16="D"),0,I16)+IF(OR(O16="G",O16="D"),0,N16)) | Q16: =IF(OR(B16="",P16=0),"-",RANK.EQ(P16,$P$6:$P$45,0)) | R16: =IF(OR(B16="",I16=0),"-",IF(OR(J16="G",J16="D"),IF(J16="G","G","D"),COUNTIF($I$6:$I$45,">"&I16)+1)) | S16: =IF(OR(B16="",N16=0),"-",IF(OR(O16="G",O16="D"),IF(O16="G","G","D"),COUNTIF($N$6:$N$45,">"&N16)+1))
A17: 12 | I17: =IF(OR(J17="G",J17="D"),0,IF(AND(F17="",G17=""),0,MAX(0,IFERROR(F17+0,0)+IFERROR(G17+0,0)-IFERROR(H17+0,0)))) | N17: =IF(OR(O17="G",O17="D"),0,IF(AND(K17="",L17=""),0,MAX(0,IFERROR(K17+0,0)+IFERROR(L17+0,0)-IFERROR(M17+0,0)))) | P17: =IF(B17="","",IF(OR(J17="G",J17="D"),0,I17)+IF(OR(O17="G",O17="D"),0,N17)) | Q17: =IF(OR(B17="",P17=0),"-",RANK.EQ(P17,$P$6:$P$45,0)) | R17: =IF(OR(B17="",I17=0),"-",IF(OR(J17="G",J17="D"),IF(J17="G","G","D"),COUNTIF($I$6:$I$45,">"&I17)+1)) | S17: =IF(OR(B17="",N17=0),"-",IF(OR(O17="G",O17="D"),IF(O17="G","G","D"),COUNTIF($N$6:$N$45,">"&N17)+1))
... A45: 40 | I45: =IF(OR(J45="G",J45="D"),0,IF(AND(F45="",G45=""),0,MAX(0,IFERROR(F45+0,0)+IFERROR(G45+0,0)-IFERROR(H45+0,0)))) | N45: =IF(OR(O45="G",O45="D"),0,IF(AND(K45="",L45=""),0,MAX(0,IFERROR(K45+0,0)+IFERROR(L45+0,0)-IFERROR(M45+0,0)))) | P45: =IF(B45="","",IF(OR(J45="G",J45="D"),0,I45)+IF(OR(O45="G",O45="D"),0,N45)) | Q45: =IF(OR(B45="",P45=0),"-",RANK.EQ(P45,$P$6:$P$45,0)) | R45: =IF(OR(B45="",I45=0),"-",IF(OR(J45="G",J45="D"),IF(J45="G","G","D"),COUNTIF($I$6:$I$45,">"&I45)+1)) | S45: =IF(OR(B45="",N45=0),"-",IF(OR(O45="G",O45="D"),IF(O45="G","G","D"),COUNTIF($N$6:$N$45,">"&N45)+1))
A47: =COUNTA(B6:B45)&" sporcu kayıtlı"

Sheet MİNİK B ERKEKLER
A1: MİNİK B ERKEKLER
A2: ='YARIŞMA BİLGİLERİ'!C3&" — "&'YARIŞMA BİLGİLERİ'!C4&" | "&'YARIŞMA BİLGİLERİ'!C5
F3: YER (FX) | K3: ATLAMA (VT) | R3: ALET SIRALARI (Eleme Seçimi için)
A4: No | B4: Ad | C4: Soyad | D4: Okul / Kulüp | E4: Tür | F4: D | G4: E | H4: ND | I4: Final | J4: Dur | K4: D | L4: E | M4: ND | N4: Final | O4: Dur | P4: TOPLAM | Q4: SIRALAMA | R4: FX | S4: VT
A5: Final = MAX(0, D+E−ND) | Dur: N=Normal · G=Gecersiz · D=Yarışmadı/DNS | Mavi sütun = formül (elle girme) | Yeşil = Toplam | Sarı = Sıralama
A6: 1 | I6: =IF(OR(J6="G",J6="D"),0,IF(AND(F6="",G6=""),0,MAX(0,IFERROR(F6+0,0)+IFERROR(G6+0,0)-IFERROR(H6+0,0)))) | N6: =IF(OR(O6="G",O6="D"),0,IF(AND(K6="",L6=""),0,MAX(0,IFERROR(K6+0,0)+IFERROR(L6+0,0)-IFERROR(M6+0,0)))) | P6: =IF(B6="","",IF(OR(J6="G",J6="D"),0,I6)+IF(OR(O6="G",O6="D"),0,N6)) | Q6: =IF(OR(B6="",P6=0),"-",RANK.EQ(P6,$P$6:$P$45,0)) | R6: =IF(OR(B6="",I6=0),"-",IF(OR(J6="G",J6="D"),IF(J6="G","G","D"),COUNTIF($I$6:$I$45,">"&I6)+1)) | S6: =IF(OR(B6="",N6=0),"-",IF(OR(O6="G",O6="D"),IF(O6="G","G","D"),COUNTIF($N$6:$N$45,">"&N6)+1))
A7: 2 | I7: =IF(OR(J7="G",J7="D"),0,IF(AND(F7="",G7=""),0,MAX(0,IFERROR(F7+0,0)+IFERROR(G7+0,0)-IFERROR(H7+0,0)))) | N7: =IF(OR(O7="G",O7="D"),0,IF(AND(K7="",L7=""),0,MAX(0,IFERROR(K7+0,0)+IFERROR(L7+0,0)-IFERROR(M7+0,0)))) | P7: =IF(B7="","",IF(OR(J7="G",J7="D"),0,I7)+IF(OR(O7="G",O7="D"),0,N7)) | Q7: =IF(OR(B7="",P7=0),"-",RANK.EQ(P7,$P$6:$P$45,0)) | R7: =IF(OR(B7="",I7=0),"-",IF(OR(J7="G",J7="D"),IF(J7="G","G","D"),COUNTIF($I$6:$I$45,">"&I7)+1)) | S7: =IF(OR(B7="",N7=0),"-",IF(OR(O7="G",O7="D"),IF(O7="G","G","D"),COUNTIF($N$6:$N$45,">"&N7)+1))
A8: 3 | I8: =IF(OR(J8="G",J8="D"),0,IF(AND(F8="",G8=""),0,MAX(0,IFERROR(F8+0,0)+IFERROR(G8+0,0)-IFERROR(H8+0,0)))) | N8: =IF(OR(O8="G",O8="D"),0,IF(AND(K8="",L8=""),0,MAX(0,IFERROR(K8+0,0)+IFERROR(L8+0,0)-IFERROR(M8+0,0)))) | P8: =IF(B8="","",IF(OR(J8="G",J8="D"),0,I8)+IF(OR(O8="G",O8="D"),0,N8)) | Q8: =IF(OR(B8="",P8=0),"-",RANK.EQ(P8,$P$6:$P$45,0)) | R8: =IF(OR(B8="",I8=0),"-",IF(OR(J8="G",J8="D"),IF(J8="G","G","D"),COUNTIF($I$6:$I$45,">"&I8)+1)) | S8: =IF(OR(B8="",N8=0),"-",IF(OR(O8="G",O8="D"),IF(O8="G","G","D"),COUNTIF($N$6:$N$45,">"&N8)+1))
A9: 4 | I9: =IF(OR(J9="G",J9="D"),0,IF(AND(F9="",G9=""),0,MAX(0,IFERROR(F9+0,0)+IFERROR(G9+0,0)-IFERROR(H9+0,0)))) | N9: =IF(OR(O9="G",O9="D"),0,IF(AND(K9="",L9=""),0,MAX(0,IFERROR(K9+0,0)+IFERROR(L9+0,0)-IFERROR(M9+0,0)))) | P9: =IF(B9="","",IF(OR(J9="G",J9="D"),0,I9)+IF(OR(O9="G",O9="D"),0,N9)) | Q9: =IF(OR(B9="",P9=0),"-",RANK.EQ(P9,$P$6:$P$45,0)) | R9: =IF(OR(B9="",I9=0),"-",IF(OR(J9="G",J9="D"),IF(J9="G","G","D"),COUNTIF($I$6:$I$45,">"&I9)+1)) | S9: =IF(OR(B9="",N9=0),"-",IF(OR(O9="G",O9="D"),IF(O9="G","G","D"),COUNTIF($N$6:$N$45,">"&N9)+1))
A10: 5 | I10: =IF(OR(J10="G",J10="D"),0,IF(AND(F10="",G10=""),0,MAX(0,IFERROR(F10+0,0)+IFERROR(G10+0,0)-IFERROR(H10+0,0)))) | N10: =IF(OR(O10="G",O10="D"),0,IF(AND(K10="",L10=""),0,MAX(0,IFERROR(K10+0,0)+IFERROR(L10+0,0)-IFERROR(M10+0,0)))) | P10: =IF(B10="","",IF(OR(J10="G",J10="D"),0,I10)+IF(OR(O10="G",O10="D"),0,N10)) | Q10: =IF(OR(B10="",P10=0),"-",RANK.EQ(P10,$P$6:$P$45,0)) | R10: =IF(OR(B10="",I10=0),"-",IF(OR(J10="G",J10="D"),IF(J10="G","G","D"),COUNTIF($I$6:$I$45,">"&I10)+1)) | S10: =IF(OR(B10="",N10=0),"-",IF(OR(O10="G",O10="D"),IF(O10="G","G","D"),COUNTIF($N$6:$N$45,">"&N10)+1))
A11: 6 | I11: =IF(OR(J11="G",J11="D"),0,IF(AND(F11="",G11=""),0,MAX(0,IFERROR(F11+0,0)+IFERROR(G11+0,0)-IFERROR(H11+0,0)))) | N11: =IF(OR(O11="G",O11="D"),0,IF(AND(K11="",L11=""),0,MAX(0,IFERROR(K11+0,0)+IFERROR(L11+0,0)-IFERROR(M11+0,0)))) | P11: =IF(B11="","",IF(OR(J11="G",J11="D"),0,I11)+IF(OR(O11="G",O11="D"),0,N11)) | Q11: =IF(OR(B11="",P11=0),"-",RANK.EQ(P11,$P$6:$P$45,0)) | R11: =IF(OR(B11="",I11=0),"-",IF(OR(J11="G",J11="D"),IF(J11="G","G","D"),COUNTIF($I$6:$I$45,">"&I11)+1)) | S11: =IF(OR(B11="",N11=0),"-",IF(OR(O11="G",O11="D"),IF(O11="G","G","D"),COUNTIF($N$6:$N$45,">"&N11)+1))
A12: 7 | I12: =IF(OR(J12="G",J12="D"),0,IF(AND(F12="",G12=""),0,MAX(0,IFERROR(F12+0,0)+IFERROR(G12+0,0)-IFERROR(H12+0,0)))) | N12: =IF(OR(O12="G",O12="D"),0,IF(AND(K12="",L12=""),0,MAX(0,IFERROR(K12+0,0)+IFERROR(L12+0,0)-IFERROR(M12+0,0)))) | P12: =IF(B12="","",IF(OR(J12="G",J12="D"),0,I12)+IF(OR(O12="G",O12="D"),0,N12)) | Q12: =IF(OR(B12="",P12=0),"-",RANK.EQ(P12,$P$6:$P$45,0)) | R12: =IF(OR(B12="",I12=0),"-",IF(OR(J12="G",J12="D"),IF(J12="G","G","D"),COUNTIF($I$6:$I$45,">"&I12)+1)) | S12: =IF(OR(B12="",N12=0),"-",IF(OR(O12="G",O12="D"),IF(O12="G","G","D"),COUNTIF($N$6:$N$45,">"&N12)+1))
A13: 8 | I13: =IF(OR(J13="G",J13="D"),0,IF(AND(F13="",G13=""),0,MAX(0,IFERROR(F13+0,0)+IFERROR(G13+0,0)-IFERROR(H13+0,0)))) | N13: =IF(OR(O13="G",O13="D"),0,IF(AND(K13="",L13=""),0,MAX(0,IFERROR(K13+0,0)+IFERROR(L13+0,0)-IFERROR(M13+0,0)))) | P13: =IF(B13="","",IF(OR(J13="G",J13="D"),0,I13)+IF(OR(O13="G",O13="D"),0,N13)) | Q13: =IF(OR(B13="",P13=0),"-",RANK.EQ(P13,$P$6:$P$45,0)) | R13: =IF(OR(B13="",I13=0),"-",IF(OR(J13="G",J13="D"),IF(J13="G","G","D"),COUNTIF($I$6:$I$45,">"&I13)+1)) | S13: =IF(OR(B13="",N13=0),"-",IF(OR(O13="G",O13="D"),IF(O13="G","G","D"),COUNTIF($N$6:$N$45,">"&N13)+1))
A14: 9 | I14: =IF(OR(J14="G",J14="D"),0,IF(AND(F14="",G14=""),0,MAX(0,IFERROR(F14+0,0)+IFERROR(G14+0,0)-IFERROR(H14+0,0)))) | N14: =IF(OR(O14="G",O14="D"),0,IF(AND(K14="",L14=""),0,MAX(0,IFERROR(K14+0,0)+IFERROR(L14+0,0)-IFERROR(M14+0,0)))) | P14: =IF(B14="","",IF(OR(J14="G",J14="D"),0,I14)+IF(OR(O14="G",O14="D"),0,N14)) | Q14: =IF(OR(B14="",P14=0),"-",RANK.EQ(P14,$P$6:$P$45,0)) | R14: =IF(OR(B14="",I14=0),"-",IF(OR(J14="G",J14="D"),IF(J14="G","G","D"),COUNTIF($I$6:$I$45,">"&I14)+1)) | S14: =IF(OR(B14="",N14=0),"-",IF(OR(O14="G",O14="D"),IF(O14="G","G","D"),COUNTIF($N$6:$N$45,">"&N14)+1))
A15: 10 | I15: =IF(OR(J15="G",J15="D"),0,IF(AND(F15="",G15=""),0,MAX(0,IFERROR(F15+0,0)+IFERROR(G15+0,0)-IFERROR(H15+0,0)))) | N15: =IF(OR(O15="G",O15="D"),0,IF(AND(K15="",L15=""),0,MAX(0,IFERROR(K15+0,0)+IFERROR(L15+0,0)-IFERROR(M15+0,0)))) | P15: =IF(B15="","",IF(OR(J15="G",J15="D"),0,I15)+IF(OR(O15="G",O15="D"),0,N15)) | Q15: =IF(OR(B15="",P15=0),"-",RANK.EQ(P15,$P$6:$P$45,0)) | R15: =IF(OR(B15="",I15=0),"-",IF(OR(J15="G",J15="D"),IF(J15="G","G","D"),COUNTIF($I$6:$I$45,">"&I15)+1)) | S15: =IF(OR(B15="",N15=0),"-",IF(OR(O15="G",O15="D"),IF(O15="G","G","D"),COUNTIF($N$6:$N$45,">"&N15)+1))
A16: 11 | I16: =IF(OR(J16="G",J16="D"),0,IF(AND(F16="",G16=""),0,MAX(0,IFERROR(F16+0,0)+IFERROR(G16+0,0)-IFERROR(H16+0,0)))) | N16: =IF(OR(O16="G",O16="D"),0,IF(AND(K16="",L16=""),0,MAX(0,IFERROR(K16+0,0)+IFERROR(L16+0,0)-IFERROR(M16+0,0)))) | P16: =IF(B16="","",IF(OR(J16="G",J16="D"),0,I16)+IF(OR(O16="G",O16="D"),0,N16)) | Q16: =IF(OR(B16="",P16=0),"-",RANK.EQ(P16,$P$6:$P$45,0)) | R16: =IF(OR(B16="",I16=0),"-",IF(OR(J16="G",J16="D"),IF(J16="G","G","D"),COUNTIF($I$6:$I$45,">"&I16)+1)) | S16: =IF(OR(B16="",N16=0),"-",IF(OR(O16="G",O16="D"),IF(O16="G","G","D"),COUNTIF($N$6:$N$45,">"&N16)+1))
A17: 12 | I17: =IF(OR(J17="G",J17="D"),0,IF(AND(F17="",G17=""),0,MAX(0,IFERROR(F17+0,0)+IFERROR(G17+0,0)-IFERROR(H17+0,0)))) | N17: =IF(OR(O17="G",O17="D"),0,IF(AND(K17="",L17=""),0,MAX(0,IFERROR(K17+0,0)+IFERROR(L17+0,0)-IFERROR(M17+0,0)))) | P17: =IF(B17="","",IF(OR(J17="G",J17="D"),0,I17)+IF(OR(O17="G",O17="D"),0,N17)) | Q17: =IF(OR(B17="",P17=0),"-",RANK.EQ(P17,$P$6:$P$45,0)) | R17: =IF(OR(B17="",I17=0),"-",IF(OR(J17="G",J17="D"),IF(J17="G","G","D"),COUNTIF($I$6:$I$45,">"&I17)+1)) | S17: =IF(OR(B17="",N17=0),"-",IF(OR(O17="G",O17="D"),IF(O17="G","G","D"),COUNTIF($N$6:$N$45,">"&N17)+1))
... A45: 40 | I45: =IF(OR(J45="G",J45="D"),0,IF(AND(F45="",G45=""),0,MAX(0,IFERROR(F45+0,0)+IFERROR(G45+0,0)-IFERROR(H45+0,0)))) | N45: =IF(OR(O45="G",O45="D"),0,IF(AND(K45="",L45=""),0,MAX(0,IFERROR(K45+0,0)+IFERROR(L45+0,0)-IFERROR(M45+0,0)))) | P45: =IF(B45="","",IF(OR(J45="G",J45="D"),0,I45)+IF(OR(O45="G",O45="D"),0,N45)) | Q45: =IF(OR(B45="",P45=0),"-",RANK.EQ(P45,$P$6:$P$45,0)) | R45: =IF(OR(B45="",I45=0),"-",IF(OR(J45="G",J45="D"),IF(J45="G","G","D"),COUNTIF($I$6:$I$45,">"&I45)+1)) | S45: =IF(OR(B45="",N45=0),"-",IF(OR(O45="G",O45="D"),IF(O45="G","G","D"),COUNTIF($N$6:$N$45,">"&N45)+1))
A47: =COUNTA(B6:B45)&" sporcu kayıtlı"

Sheet KÜÇÜK KIZLAR
A1: KÜÇÜK KIZLAR
A2: ='YARIŞMA BİLGİLERİ'!C3&" — "&'YARIŞMA BİLGİLERİ'!C4&" | "&'YARIŞMA BİLGİLERİ'!C5
F3: ATLAMA (VT) | K3: AS.PARALEL (UB) | P3: DENGE (BB) | U3: SERBEST (FX) | AB3: ALET SIRALARI (Eleme Seçimi için)
A4: No | B4: Ad | C4: Soyad | D4: Okul / Kulüp | E4: Tür | F4: D | G4: E | H4: ND | I4: Final | J4: Dur | K4: D | L4: E | M4: ND | N4: Final | O4: Dur | P4: D | Q4: E | R4: ND | S4: Final | T4: Dur | U4: D | V4: E | W4: ND | X4: Final | Y4: Dur | Z4: TOPLAM | AA4: SIRALAMA | AB4: VT | AC4: UB | AD4: BB | AE4: FX
A5: Final = MAX(0, D+E−ND) | Dur: N=Normal · G=Gecersiz · D=Yarışmadı/DNS | Mavi sütun = formül (elle girme) | Yeşil = Toplam | Sarı = Sıralama
A6: 1 | I6: =IF(OR(J6="G",J6="D"),0,IF(AND(F6="",G6=""),0,MAX(0,IFERROR(F6+0,0)+IFERROR(G6+0,0)-IFERROR(H6+0,0)))) | N6: =IF(OR(O6="G",O6="D"),0,IF(AND(K6="",L6=""),0,MAX(0,IFERROR(K6+0,0)+IFERROR(L6+0,0)-IFERROR(M6+0,0)))) | S6: =IF(OR(T6="G",T6="D"),0,IF(AND(P6="",Q6=""),0,MAX(0,IFERROR(P6+0,0)+IFERROR(Q6+0,0)-IFERROR(R6+0,0)))) | X6: =IF(OR(Y6="G",Y6="D"),0,IF(AND(U6="",V6=""),0,MAX(0,IFERROR(U6+0,0)+IFERROR(V6+0,0)-IFERROR(W6+0,0)))) | Z6: =IF(B6="","",IF(OR(J6="G",J6="D"),0,I6)+IF(OR(O6="G",O6="D"),0,N6)+IF(OR(T6="G",T6="D"),0,S6)+IF(OR(Y6="G",Y6="D"),0,X6)) | AA6: =IF(OR(B6="",Z6=0),"-",RANK.EQ(Z6,$Z$6:$Z$45,0)) | AB6: =IF(OR(B6="",I6=0),"-",IF(OR(J6="G",J6="D"),IF(J6="G","G","D"),COUNTIF($I$6:$I$45,">"&I6)+1)) | AC6: =IF(OR(B6="",N6=0),"-",IF(OR(O6="G",O6="D"),IF(O6="G","G","D"),COUNTIF($N$6:$N$45,">"&N6)+1)) | AD6: =IF(OR(B6="",S6=0),"-",IF(OR(T6="G",T6="D"),IF(T6="G","G","D"),COUNTIF($S$6:$S$45,">"&S6)+1)) | AE6: =IF(OR(B6="",X6=0),"-",IF(OR(Y6="G",Y6="D"),IF(Y6="G","G","D"),COUNTIF($X$6:$X$45,">"&X6)+1))
A7: 2 | I7: =IF(OR(J7="G",J7="D"),0,IF(AND(F7="",G7=""),0,MAX(0,IFERROR(F7+0,0)+IFERROR(G7+0,0)-IFERROR(H7+0,0)))) | N7: =IF(OR(O7="G",O7="D"),0,IF(AND(K7="",L7=""),0,MAX(0,IFERROR(K7+0,0)+IFERROR(L7+0,0)-IFERROR(M7+0,0)))) | S7: =IF(OR(T7="G",T7="D"),0,IF(AND(P7="",Q7=""),0,MAX(0,IFERROR(P7+0,0)+IFERROR(Q7+0,0)-IFERROR(R7+0,0)))) | X7: =IF(OR(Y7="G",Y7="D"),0,IF(AND(U7="",V7=""),0,MAX(0,IFERROR(U7+0,0)+IFERROR(V7+0,0)-IFERROR(W7+0,0)))) | Z7: =IF(B7="","",IF(OR(J7="G",J7="D"),0,I7)+IF(OR(O7="G",O7="D"),0,N7)+IF(OR(T7="G",T7="D"),0,S7)+IF(OR(Y7="G",Y7="D"),0,X7)) | AA7: =IF(OR(B7="",Z7=0),"-",RANK.EQ(Z7,$Z$6:$Z$45,0)) | AB7: =IF(OR(B7="",I7=0),"-",IF(OR(J7="G",J7="D"),IF(J7="G","G","D"),COUNTIF($I$6:$I$45,">"&I7)+1)) | AC7: =IF(OR(B7="",N7=0),"-",IF(OR(O7="G",O7="D"),IF(O7="G","G","D"),COUNTIF($N$6:$N$45,">"&N7)+1)) | AD7: =IF(OR(B7="",S7=0),"-",IF(OR(T7="G",T7="D"),IF(T7="G","G","D"),COUNTIF($S$6:$S$45,">"&S7)+1)) | AE7: =IF(OR(B7="",X7=0),"-",IF(OR(Y7="G",Y7="D"),IF(Y7="G","G","D"),COUNTIF($X$6:$X$45,">"&X7)+1))
A8: 3 | I8: =IF(OR(J8="G",J8="D"),0,IF(AND(F8="",G8=""),0,MAX(0,IFERROR(F8+0,0)+IFERROR(G8+0,0)-IFERROR(H8+0,0)))) | N8: =IF(OR(O8="G",O8="D"),0,IF(AND(K8="",L8=""),0,MAX(0,IFERROR(K8+0,0)+IFERROR(L8+0,0)-IFERROR(M8+0,0)))) | S8: =IF(OR(T8="G",T8="D"),0,IF(AND(P8="",Q8=""),0,MAX(0,IFERROR(P8+0,0)+IFERROR(Q8+0,0)-IFERROR(R8+0,0)))) | X8: =IF(OR(Y8="G",Y8="D"),0,IF(AND(U8="",V8=""),0,MAX(0,IFERROR(U8+0,0)+IFERROR(V8+0,0)-IFERROR(W8+0,0)))) | Z8: =IF(B8="","",IF(OR(J8="G",J8="D"),0,I8)+IF(OR(O8="G",O8="D"),0,N8)+IF(OR(T8="G",T8="D"),0,S8)+IF(OR(Y8="G",Y8="D"),0,X8)) | AA8: =IF(OR(B8="",Z8=0),"-",RANK.EQ(Z8,$Z$6:$Z$45,0)) | AB8: =IF(OR(B8="",I8=0),"-",IF(OR(J8="G",J8="D"),IF(J8="G","G","D"),COUNTIF($I$6:$I$45,">"&I8)+1)) | AC8: =IF(OR(B8="",N8=0),"-",IF(OR(O8="G",O8="D"),IF(O8="G","G","D"),COUNTIF($N$6:$N$45,">"&N8)+1)) | AD8: =IF(OR(B8="",S8=0),"-",IF(OR(T8="G",T8="D"),IF(T8="G","G","D"),COUNTIF($S$6:$S$45,">"&S8)+1)) | AE8: =IF(OR(B8="",X8=0),"-",IF(OR(Y8="G",Y8="D"),IF(Y8="G","G","D"),COUNTIF($X$6:$X$45,">"&X8)+1))
A9: 4 | I9: =IF(OR(J9="G",J9="D"),0,IF(AND(F9="",G9=""),0,MAX(0,IFERROR(F9+0,0)+IFERROR(G9+0,0)-IFERROR(H9+0,0)))) | N9: =IF(OR(O9="G",O9="D"),0,IF(AND(K9="",L9=""),0,MAX(0,IFERROR(K9+0,0)+IFERROR(L9+0,0)-IFERROR(M9+0,0)))) | S9: =IF(OR(T9="G",T9="D"),0,IF(AND(P9="",Q9=""),0,MAX(0,IFERROR(P9+0,0)+IFERROR(Q9+0,0)-IFERROR(R9+0,0)))) | X9: =IF(OR(Y9="G",Y9="D"),0,IF(AND(U9="",V9=""),0,MAX(0,IFERROR(U9+0,0)+IFERROR(V9+0,0)-IFERROR(W9+0,0)))) | Z9: =IF(B9="","",IF(OR(J9="G",J9="D"),0,I9)+IF(OR(O9="G",O9="D"),0,N9)+IF(OR(T9="G",T9="D"),0,S9)+IF(OR(Y9="G",Y9="D"),0,X9)) | AA9: =IF(OR(B9="",Z9=0),"-",RANK.EQ(Z9,$Z$6:$Z$45,0)) | AB9: =IF(OR(B9="",I9=0),"-",IF(OR(J9="G",J9="D"),IF(J9="G","G","D"),COUNTIF($I$6:$I$45,">"&I9)+1)) | AC9: =IF(OR(B9="",N9=0),"-",IF(OR(O9="G",O9="D"),IF(O9="G","G","D"),COUNTIF($N$6:$N$45,">"&N9)+1)) | AD9: =IF(OR(B9="",S9=0),"-",IF(OR(T9="G",T9="D"),IF(T9="G","G","D"),COUNTIF($S$6:$S$45,">"&S9)+1)) | AE9: =IF(OR(B9="",X9=0),"-",IF(OR(Y9="G",Y9="D"),IF(Y9="G","G","D"),COUNTIF($X$6:$X$45,">"&X9)+1))
A10: 5 | I10: =IF(OR(J10="G",J10="D"),0,IF(AND(F10="",G10=""),0,MAX(0,IFERROR(F10+0,0)+IFERROR(G10+0,0)-IFERROR(H10+0,0)))) | N10: =IF(OR(O10="G",O10="D"),0,IF(AND(K10="",L10=""),0,MAX(0,IFERROR(K10+0,0)+IFERROR(L10+0,0)-IFERROR(M10+0,0)))) | S10: =IF(OR(T10="G",T10="D"),0,IF(AND(P10="",Q10=""),0,MAX(0,IFERROR(P10+0,0)+IFERROR(Q10+0,0)-IFERROR(R10+0,0)))) | X10: =IF(OR(Y10="G",Y10="D"),0,IF(AND(U10="",V10=""),0,MAX(0,IFERROR(U10+0,0)+IFERROR(V10+0,0)-IFERROR(W10+0,0)))) | Z10: =IF(B10="","",IF(OR(J10="G",J10="D"),0,I10)+IF(OR(O10="G",O10="D"),0,N10)+IF(OR(T10="G",T10="D"),0,S10)+IF(OR(Y10="G",Y10="D"),0,X10)) | AA10: =IF(OR(B10="",Z10=0),"-",RANK.EQ(Z10,$Z$6:$Z$45,0)) | AB10: =IF(OR(B10="",I10=0),"-",IF(OR(J10="G",J10="D"),IF(J10="G","G","D"),COUNTIF($I$6:$I$45,">"&I10)+1)) | AC10: =IF(OR(B10="",N10=0),"-",IF(OR(O10="G",O10="D"),IF(O10="G","G","D"),COUNTIF($N$6:$N$45,">"&N10)+1)) | AD10: =IF(OR(B10="",S10=0),"-",IF(OR(T10="G",T10="D"),IF(T10="G","G","D"),COUNTIF($S$6:$S$45,">"&S10)+1)) | AE10: =IF(OR(B10="",X10=0),"-",IF(OR(Y10="G",Y10="D"),IF(Y10="G","G","D"),COUNTIF($X$6:$X$45,">"&X10)+1))
A11: 6 | I11: =IF(OR(J11="G",J11="D"),0,IF(AND(F11="",G11=""),0,MAX(0,IFERROR(F11+0,0)+IFERROR(G11+0,0)-IFERROR(H11+0,0)))) | N11: =IF(OR(O11="G",O11="D"),0,IF(AND(K11="",L11=""),0,MAX(0,IFERROR(K11+0,0)+IFERROR(L11+0,0)-IFERROR(M11+0,0)))) | S11: =IF(OR(T11="G",T11="D"),0,IF(AND(P11="",Q11=""),0,MAX(0,IFERROR(P11+0,0)+IFERROR(Q11+0,0)-IFERROR(R11+0,0)))) | X11: =IF(OR(Y11="G",Y11="D"),0,IF(AND(U11="",V11=""),0,MAX(0,IFERROR(U11+0,0)+IFERROR(V11+0,0)-IFERROR(W11+0,0)))) | Z11: =IF(B11="","",IF(OR(J11="G",J11="D"),0,I11)+IF(OR(O11="G",O11="D"),0,N11)+IF(OR(T11="G",T11="D"),0,S11)+IF(OR(Y11="G",Y11="D"),0,X11)) | AA11: =IF(OR(B11="",Z11=0),"-",RANK.EQ(Z11,$Z$6:$Z$45,0)) | AB11: =IF(OR(B11="",I11=0),"-",IF(OR(J11="G",J11="D"),IF(J11="G","G","D"),COUNTIF($I$6:$I$45,">"&I11)+1)) | AC11: =IF(OR(B11="",N11=0),"-",IF(OR(O11="G",O11="D"),IF(O11="G","G","D"),COUNTIF($N$6:$N$45,">"&N11)+1)) | AD11: =IF(OR(B11="",S11=0),"-",IF(OR(T11="G",T11="D"),IF(T11="G","G","D"),COUNTIF($S$6:$S$45,">"&S11)+1)) | AE11: =IF(OR(B11="",X11=0),"-",IF(OR(Y11="G",Y11="D"),IF(Y11="G","G","D"),COUNTIF($X$6:$X$45,">"&X11)+1))
A12: 7 | I12: =IF(OR(J12="G",J12="D"),0,IF(AND(F12="",G12=""),0,MAX(0,IFERROR(F12+0,0)+IFERROR(G12+0,0)-IFERROR(H12+0,0)))) | N12: =IF(OR(O12="G",O12="D"),0,IF(AND(K12="",L12=""),0,MAX(0,IFERROR(K12+0,0)+IFERROR(L12+0,0)-IFERROR(M12+0,0)))) | S12: =IF(OR(T12="G",T12="D"),0,IF(AND(P12="",Q12=""),0,MAX(0,IFERROR(P12+0,0)+IFERROR(Q12+0,0)-IFERROR(R12+0,0)))) | X12: =IF(OR(Y12="G",Y12="D"),0,IF(AND(U12="",V12=""),0,MAX(0,IFERROR(U12+0,0)+IFERROR(V12+0,0)-IFERROR(W12+0,0)))) | Z12: =IF(B12="","",IF(OR(J12="G",J12="D"),0,I12)+IF(OR(O12="G",O12="D"),0,N12)+IF(OR(T12="G",T12="D"),0,S12)+IF(OR(Y12="G",Y12="D"),0,X12)) | AA12: =IF(OR(B12="",Z12=0),"-",RANK.EQ(Z12,$Z$6:$Z$45,0)) | AB12: =IF(OR(B12="",I12=0),"-",IF(OR(J12="G",J12="D"),IF(J12="G","G","D"),COUNTIF($I$6:$I$45,">"&I12)+1)) | AC12: =IF(OR(B12="",N12=0),"-",IF(OR(O12="G",O12="D"),IF(O12="G","G","D"),COUNTIF($N$6:$N$45,">"&N12)+1)) | AD12: =IF(OR(B12="",S12=0),"-",IF(OR(T12="G",T12="D"),IF(T12="G","G","D"),COUNTIF($S$6:$S$45,">"&S12)+1)) | AE12: =IF(OR(B12="",X12=0),"-",IF(OR(Y12="G",Y12="D"),IF(Y12="G","G","D"),COUNTIF($X$6:$X$45,">"&X12)+1))
A13: 8 | I13: =IF(OR(J13="G",J13="D"),0,IF(AND(F13="",G13=""),0,MAX(0,IFERROR(F13+0,0)+IFERROR(G13+0,0)-IFERROR(H13+0,0)))) | N13: =IF(OR(O13="G",O13="D"),0,IF(AND(K13="",L13=""),0,MAX(0,IFERROR(K13+0,0)+IFERROR(L13+0,0)-IFERROR(M13+0,0)))) | S13: =IF(OR(T13="G",T13="D"),0,IF(AND(P13="",Q13=""),0,MAX(0,IFERROR(P13+0,0)+IFERROR(Q13+0,0)-IFERROR(R13+0,0)))) | X13: =IF(OR(Y13="G",Y13="D"),0,IF(AND(U13="",V13=""),0,MAX(0,IFERROR(U13+0,0)+IFERROR(V13+0,0)-IFERROR(W13+0,0)))) | Z13: =IF(B13="","",IF(OR(J13="G",J13="D"),0,I13)+IF(OR(O13="G",O13="D"),0,N13)+IF(OR(T13="G",T13="D"),0,S13)+IF(OR(Y13="G",Y13="D"),0,X13)) | AA13: =IF(OR(B13="",Z13=0),"-",RANK.EQ(Z13,$Z$6:$Z$45,0)) | AB13: =IF(OR(B13="",I13=0),"-",IF(OR(J13="G",J13="D"),IF(J13="G","G","D"),COUNTIF($I$6:$I$45,">"&I13)+1)) | AC13: =IF(OR(B13="",N13=0),"-",IF(OR(O13="G",O13="D"),IF(O13="G","G","D"),COUNTIF($N$6:$N$45,">"&N13)+1)) | AD13: =IF(OR(B13="",S13=0),"-",IF(OR(T13="G",T13="D"),IF(T13="G","G","D"),COUNTIF($S$6:$S$45,">"&S13)+1)) | AE13: =IF(OR(B13="",X13=0),"-",IF(OR(Y13="G",Y13="D"),IF(Y13="G","G","D"),COUNTIF($X$6:$X$45,">"&X13)+1))
A14: 9 | I14: =IF(OR(J14="G",J14="D"),0,IF(AND(F14="",G14=""),0,MAX(0,IFERROR(F14+0,0)+IFERROR(G14+0,0)-IFERROR(H14+0,0)))) | N14: =IF(OR(O14="G",O14="D"),0,IF(AND(K14="",L14=""),0,MAX(0,IFERROR(K14+0,0)+IFERROR(L14+0,0)-IFERROR(M14+0,0)))) | S14: =IF(OR(T14="G",T14="D"),0,IF(AND(P14="",Q14=""),0,MAX(0,IFERROR(P14+0,0)+IFERROR(Q14+0,0)-IFERROR(R14+0,0)))) | X14: =IF(OR(Y14="G",Y14="D"),0,IF(AND(U14="",V14=""),0,MAX(0,IFERROR(U14+0,0)+IFERROR(V14+0,0)-IFERROR(W14+0,0)))) | Z14: =IF(B14="","",IF(OR(J14="G",J14="D"),0,I14)+IF(OR(O14="G",O14="D"),0,N14)+IF(OR(T14="G",T14="D"),0,S14)+IF(OR(Y14="G",Y14="D"),0,X14)) | AA14: =IF(OR(B14="",Z14=0),"-",RANK.EQ(Z14,$Z$6:$Z$45,0)) | AB14: =IF(OR(B14="",I14=0),"-",IF(OR(J14="G",J14="D"),IF(J14="G","G","D"),COUNTIF($I$6:$I$45,">"&I14)+1)) | AC14: =IF(OR(B14="",N14=0),"-",IF(OR(O14="G",O14="D"),IF(O14="G","G","D"),COUNTIF($N$6:$N$45,">"&N14)+1)) | AD14: =IF(OR(B14="",S14=0),"-",IF(OR(T14="G",T14="D"),IF(T14="G","G","D"),COUNTIF($S$6:$S$45,">"&S14)+1)) | AE14: =IF(OR(B14="",X14=0),"-",IF(OR(Y14="G",Y14="D"),IF(Y14="G","G","D"),COUNTIF($X$6:$X$45,">"&X14)+1))
A15: 10 | I15: =IF(OR(J15="G",J15="D"),0,IF(AND(F15="",G15=""),0,MAX(0,IFERROR(F15+0,0)+IFERROR(G15+0,0)-IFERROR(H15+0,0)))) | N15: =IF(OR(O15="G",O15="D"),0,IF(AND(K15="",L15=""),0,MAX(0,IFERROR(K15+0,0)+IFERROR(L15+0,0)-IFERROR(M15+0,0)))) | S15: =IF(OR(T15="G",T15="D"),0,IF(AND(P15="",Q15=""),0,MAX(0,IFERROR(P15+0,0)+IFERROR(Q15+0,0)-IFERROR(R15+0,0)))) | X15: =IF(OR(Y15="G",Y15="D"),0,IF(AND(U15="",V15=""),0,MAX(0,IFERROR(U15+0,0)+IFERROR(V15+0,0)-IFERROR(W15+0,0)))) | Z15: =IF(B15="","",IF(OR(J15="G",J15="D"),0,I15)+IF(OR(O15="G",O15="D"),0,N15)+IF(OR(T15="G",T15="D"),0,S15)+IF(OR(Y15="G",Y15="D"),0,X15)) | AA15: =IF(OR(B15="",Z15=0),"-",RANK.EQ(Z15,$Z$6:$Z$45,0)) | AB15: =IF(OR(B15="",I15=0),"-",IF(OR(J15="G",J15="D"),IF(J15="G","G","D"),COUNTIF($I$6:$I$45,">"&I15)+1)) | AC15: =IF(OR(B15="",N15=0),"-",IF(OR(O15="G",O15="D"),IF(O15="G","G","D"),COUNTIF($N$6:$N$45,">"&N15)+1)) | AD15: =IF(OR(B15="",S15=0),"-",IF(OR(T15="G",T15="D"),IF(T15="G","G","D"),COUNTIF($S$6:$S$45,">"&S15)+1)) | AE15: =IF(OR(B15="",X15=0),"-",IF(OR(Y15="G",Y15="D"),IF(Y15="G","G","D"),COUNTIF($X$6:$X$45,">"&X15)+1))
A16: 11 | I16: =IF(OR(J16="G",J16="D"),0,IF(AND(F16="",G16=""),0,MAX(0,IFERROR(F16+0,0)+IFERROR(G16+0,0)-IFERROR(H16+0,0)))) | N16: =IF(OR(O16="G",O16="D"),0,IF(AND(K16="",L16=""),0,MAX(0,IFERROR(K16+0,0)+IFERROR(L16+0,0)-IFERROR(M16+0,0)))) | S16: =IF(OR(T16="G",T16="D"),0,IF(AND(P16="",Q16=""),0,MAX(0,IFERROR(P16+0,0)+IFERROR(Q16+0,0)-IFERROR(R16+0,0)))) | X16: =IF(OR(Y16="G",Y16="D"),0,IF(AND(U16="",V16=""),0,MAX(0,IFERROR(U16+0,0)+IFERROR(V16+0,0)-IFERROR(W16+0,0)))) | Z16: =IF(B16="","",IF(OR(J16="G",J16="D"),0,I16)+IF(OR(O16="G",O16="D"),0,N16)+IF(OR(T16="G",T16="D"),0,S16)+IF(OR(Y16="G",Y16="D"),0,X16)) | AA16: =IF(OR(B16="",Z16=0),"-",RANK.EQ(Z16,$Z$6:$Z$45,0)) | AB16: =IF(OR(B16="",I16=0),"-",IF(OR(J16="G",J16="D"),IF(J16="G","G","D"),COUNTIF($I$6:$I$45,">"&I16)+1)) | AC16: =IF(OR(B16="",N16=0),"-",IF(OR(O16="G",O16="D"),IF(O16="G","G","D"),COUNTIF($N$6:$N$45,">"&N16)+1)) | AD16: =IF(OR(B16="",S16=0),"-",IF(OR(T16="G",T16="D"),IF(T16="G","G","D"),COUNTIF($S$6:$S$45,">"&S16)+1)) | AE16: =IF(OR(B16="",X16=0),"-",IF(OR(Y16="G",Y16="D"),IF(Y16="G","G","D"),COUNTIF($X$6:$X$45,">"&X16)+1))
A17: 12 | I17: =IF(OR(J17="G",J17="D"),0,IF(AND(F17="",G17=""),0,MAX(0,IFERROR(F17+0,0)+IFERROR(G17+0,0)-IFERROR(H17+0,0)))) | N17: =IF(OR(O17="G",O17="D"),0,IF(AND(K17="",L17=""),0,MAX(0,IFERROR(K17+0,0)+IFERROR(L17+0,0)-IFERROR(M17+0,0)))) | S17: =IF(OR(T17="G",T17="D"),0,IF(AND(P17="",Q17=""),0,MAX(0,IFERROR(P17+0,0)+IFERROR(Q17+0,0)-IFERROR(R17+0,0)))) | X17: =IF(OR(Y17="G",Y17="D"),0,IF(AND(U17="",V17=""),0,MAX(0,IFERROR(U17+0,0)+IFERROR(V17+0,0)-IFERROR(W17+0,0)))) | Z17: =IF(B17="","",IF(OR(J17="G",J17="D"),0,I17)+IF(OR(O17="G",O17="D"),0,N17)+IF(OR(T17="G",T17="D"),0,S17)+IF(OR(Y17="G",Y17="D"),0,X17)) | AA17: =IF(OR(B17="",Z17=0),"-",RANK.EQ(Z17,$Z$6:$Z$45,0)) | AB17: =IF(OR(B17="",I17=0),"-",IF(OR(J17="G",J17="D"),IF(J17="G","G","D"),COUNTIF($I$6:$I$45,">"&I17)+1)) | AC17: =IF(OR(B17="",N17=0),"-",IF(OR(O17="G",O17="D"),IF(O17="G","G","D"),COUNTIF($N$6:$N$45,">"&N17)+1)) | AD17: =IF(OR(B17="",S17=0),"-",IF(OR(T17="G",T17="D"),IF(T17="G","G","D"),COUNTIF($S$6:$S$45,">"&S17)+1)) | AE17: =IF(OR(B17="",X17=0),"-",IF(OR(Y17="G",Y17="D"),IF(Y17="G","G","D"),COUNTIF($X$6:$X$45,">"&X17)+1))
... A45: 40 | I45: =IF(OR(J45="G",J45="D"),0,IF(AND(F45="",G45=""),0,MAX(0,IFERROR(F45+0,0)+IFERROR(G45+0,0)-IFERROR(H45+0,0)))) | N45: =IF(OR(O45="G",O45="D"),0,IF(AND(K45="",L45=""),0,MAX(0,IFERROR(K45+0,0)+IFERROR(L45+0,0)-IFERROR(M45+0,0)))) | S45: =IF(OR(T45="G",T45="D"),0,IF(AND(P45="",Q45=""),0,MAX(0,IFERROR(P45+0,0)+IFERROR(Q45+0,0)-IFERROR(R45+0,0)))) | X45: =IF(OR(Y45="G",Y45="D"),0,IF(AND(U45="",V45=""),0,MAX(0,IFERROR(U45+0,0)+IFERROR(V45+0,0)-IFERROR(W45+0,0)))) | Z45: =IF(B45="","",IF(OR(J45="G",J45="D"),0,I45)+IF(OR(O45="G",O45="D"),0,N45)+IF(OR(T45="G",T45="D"),0,S45)+IF(OR(Y45="G",Y45="D"),0,X45)) | AA45: =IF(OR(B45="",Z45=0),"-",RANK.EQ(Z45,$Z$6:$Z$45,0)) | AB45: =IF(OR(B45="",I45=0),"-",IF(OR(J45="G",J45="D"),IF(J45="G","G","D"),COUNTIF($I$6:$I$45,">"&I45)+1)) | AC45: =IF(OR(B45="",N45=0),"-",IF(OR(O45="G",O45="D"),IF(O45="G","G","D"),COUNTIF($N$6:$N$45,">"&N45)+1)) | AD45: =IF(OR(B45="",S45=0),"-",IF(OR(T45="G",T45="D"),IF(T45="G","G","D"),COUNTIF($S$6:$S$45,">"&S45)+1)) | AE45: =IF(OR(B45="",X45=0),"-",IF(OR(Y45="G",Y45="D"),IF(Y45="G","G","D"),COUNTIF($X$6:$X$45,">"&X45)+1))
A47: =COUNTA(B6:B45)&" sporcu kayıtlı"

Sheet KÜÇÜK ERKEKLER
A1: KÜÇÜK ERKEKLER
A2: ='YARIŞMA BİLGİLERİ'!C3&" — "&'YARIŞMA BİLGİLERİ'!C4&" | "&'YARIŞMA BİLGİLERİ'!C5
F3: YER (FX) | K3: ATLAMA (VT) | P3: PARALEL (PB) | U3: BARFIKS (HB) | AB3: ALET SIRALARI (Eleme Seçimi için)
A4: No | B4: Ad | C4: Soyad | D4: Okul / Kulüp | E4: Tür | F4: D | G4: E | H4: ND | I4: Final | J4: Dur | K4: D | L4: E | M4: ND | N4: Final | O4: Dur | P4: D | Q4: E | R4: ND | S4: Final | T4: Dur | U4: D | V4: E | W4: ND | X4: Final | Y4: Dur | Z4: TOPLAM | AA4: SIRALAMA | AB4: FX | AC4: VT | AD4: PB | AE4: HB
A5: Final = MAX(0, D+E−ND) | Dur: N=Normal · G=Gecersiz · D=Yarışmadı/DNS | Mavi sütun = formül (elle girme) | Yeşil = Toplam | Sarı = Sıralama
A6: 1 | I6: =IF(OR(J6="G",J6="D"),0,IF(AND(F6="",G6=""),0,MAX(0,IFERROR(F6+0,0)+IFERROR(G6+0,0)-IFERROR(H6+0,0)))) | N6: =IF(OR(O6="G",O6="D"),0,IF(AND(K6="",L6=""),0,MAX(0,IFERROR(K6+0,0)+IFERROR(L6+0,0)-IFERROR(M6+0,0)))) | S6: =IF(OR(T6="G",T6="D"),0,IF(AND(P6="",Q6=""),0,MAX(0,IFERROR(P6+0,0)+IFERROR(Q6+0,0)-IFERROR(R6+0,0)))) | X6: =IF(OR(Y6="G",Y6="D"),0,IF(AND(U6="",V6=""),0,MAX(0,IFERROR(U6+0,0)+IFERROR(V6+0,0)-IFERROR(W6+0,0)))) | Z6: =IF(B6="","",IF(OR(J6="G",J6="D"),0,I6)+IF(OR(O6="G",O6="D"),0,N6)+IF(OR(T6="G",T6="D"),0,S6)+IF(OR(Y6="G",Y6="D"),0,X6)) | AA6: =IF(OR(B6="",Z6=0),"-",RANK.EQ(Z6,$Z$6:$Z$45,0)) | AB6: =IF(OR(B6="",I6=0),"-",IF(OR(J6="G",J6="D"),IF(J6="G","G","D"),COUNTIF($I$6:$I$45,">"&I6)+1)) | AC6: =IF(OR(B6="",N6=0),"-",IF(OR(O6="G",O6="D"),IF(O6="G","G","D"),COUNTIF($N$6:$N$45,">"&N6)+1)) | AD6: =IF(OR(B6="",S6=0),"-",IF(OR(T6="G",T6="D"),IF(T6="G","G","D"),COUNTIF($S$6:$S$45,">"&S6)+1)) | AE6: =IF(OR(B6="",X6=0),"-",IF(OR(Y6="G",Y6="D"),IF(Y6="G","G","D"),COUNTIF($X$6:$X$45,">"&X6)+1))
A7: 2 | I7: =IF(OR(J7="G",J7="D"),0,IF(AND(F7="",G7=""),0,MAX(0,IFERROR(F7+0,0)+IFERROR(G7+0,0)-IFERROR(H7+0,0)))) | N7: =IF(OR(O7="G",O7="D"),0,IF(AND(K7="",L7=""),0,MAX(0,IFERROR(K7+0,0)+IFERROR(L7+0,0)-IFERROR(M7+0,0)))) | S7: =IF(OR(T7="G",T7="D"),0,IF(AND(P7="",Q7=""),0,MAX(0,IFERROR(P7+0,0)+IFERROR(Q7+0,0)-IFERROR(R7+0,0)))) | X7: =IF(OR(Y7="G",Y7="D"),0,IF(AND(U7="",V7=""),0,MAX(0,IFERROR(U7+0,0)+IFERROR(V7+0,0)-IFERROR(W7+0,0)))) | Z7: =IF(B7="","",IF(OR(J7="G",J7="D"),0,I7)+IF(OR(O7="G",O7="D"),0,N7)+IF(OR(T7="G",T7="D"),0,S7)+IF(OR(Y7="G",Y7="D"),0,X7)) | AA7: =IF(OR(B7="",Z7=0),"-",RANK.EQ(Z7,$Z$6:$Z$45,0)) | AB7: =IF(OR(B7="",I7=0),"-",IF(OR(J7="G",J7="D"),IF(J7="G","G","D"),COUNTIF($I$6:$I$45,">"&I7)+1)) | AC7: =IF(OR(B7="",N7=0),"-",IF(OR(O7="G",O7="D"),IF(O7="G","G","D"),COUNTIF($N$6:$N$45,">"&N7)+1)) | AD7: =IF(OR(B7="",S7=0),"-",IF(OR(T7="G",T7="D"),IF(T7="G","G","D"),COUNTIF($S$6:$S$45,">"&S7)+1)) | AE7: =IF(OR(B7="",X7=0),"-",IF(OR(Y7="G",Y7="D"),IF(Y7="G","G","D"),COUNTIF($X$6:$X$45,">"&X7)+1))
A8: 3 | I8: =IF(OR(J8="G",J8="D"),0,IF(AND(F8="",G8=""),0,MAX(0,IFERROR(F8+0,0)+IFERROR(G8+0,0)-IFERROR(H8+0,0)))) | N8: =IF(OR(O8="G",O8="D"),0,IF(AND(K8="",L8=""),0,MAX(0,IFERROR(K8+0,0)+IFERROR(L8+0,0)-IFERROR(M8+0,0)))) | S8: =IF(OR(T8="G",T8="D"),0,IF(AND(P8="",Q8=""),0,MAX(0,IFERROR(P8+0,0)+IFERROR(Q8+0,0)-IFERROR(R8+0,0)))) | X8: =IF(OR(Y8="G",Y8="D"),0,IF(AND(U8="",V8=""),0,MAX(0,IFERROR(U8+0,0)+IFERROR(V8+0,0)-IFERROR(W8+0,0)))) | Z8: =IF(B8="","",IF(OR(J8="G",J8="D"),0,I8)+IF(OR(O8="G",O8="D"),0,N8)+IF(OR(T8="G",T8="D"),0,S8)+IF(OR(Y8="G",Y8="D"),0,X8)) | AA8: =IF(OR(B8="",Z8=0),"-",RANK.EQ(Z8,$Z$6:$Z$45,0)) | AB8: =IF(OR(B8="",I8=0),"-",IF(OR(J8="G",J8="D"),IF(J8="G","G","D"),COUNTIF($I$6:$I$45,">"&I8)+1)) | AC8: =IF(OR(B8="",N8=0),"-",IF(OR(O8="G",O8="D"),IF(O8="G","G","D"),COUNTIF($N$6:$N$45,">"&N8)+1)) | AD8: =IF(OR(B8="",S8=0),"-",IF(OR(T8="G",T8="D"),IF(T8="G","G","D"),COUNTIF($S$6:$S$45,">"&S8)+1)) | AE8: =IF(OR(B8="",X8=0),"-",IF(OR(Y8="G",Y8="D"),IF(Y8="G","G","D"),COUNTIF($X$6:$X$45,">"&X8)+1))
A9: 4 | I9: =IF(OR(J9="G",J9="D"),0,IF(AND(F9="",G9=""),0,MAX(0,IFERROR(F9+0,0)+IFERROR(G9+0,0)-IFERROR(H9+0,0)))) | N9: =IF(OR(O9="G",O9="D"),0,IF(AND(K9="",L9=""),0,MAX(0,IFERROR(K9+0,0)+IFERROR(L9+0,0)-IFERROR(M9+0,0)))) | S9: =IF(OR(T9="G",T9="D"),0,IF(AND(P9="",Q9=""),0,MAX(0,IFERROR(P9+0,0)+IFERROR(Q9+0,0)-IFERROR(R9+0,0)))) | X9: =IF(OR(Y9="G",Y9="D"),0,IF(AND(U9="",V9=""),0,MAX(0,IFERROR(U9+0,0)+IFERROR(V9+0,0)-IFERROR(W9+0,0)))) | Z9: =IF(B9="","",IF(OR(J9="G",J9="D"),0,I9)+IF(OR(O9="G",O9="D"),0,N9)+IF(OR(T9="G",T9="D"),0,S9)+IF(OR(Y9="G",Y9="D"),0,X9)) | AA9: =IF(OR(B9="",Z9=0),"-",RANK.EQ(Z9,$Z$6:$Z$45,0)) | AB9: =IF(OR(B9="",I9=0),"-",IF(OR(J9="G",J9="D"),IF(J9="G","G","D"),COUNTIF($I$6:$I$45,">"&I9)+1)) | AC9: =IF(OR(B9="",N9=0),"-",IF(OR(O9="G",O9="D"),IF(O9="G","G","D"),COUNTIF($N$6:$N$45,">"&N9)+1)) | AD9: =IF(OR(B9="",S9=0),"-",IF(OR(T9="G",T9="D"),IF(T9="G","G","D"),COUNTIF($S$6:$S$45,">"&S9)+1)) | AE9: =IF(OR(B9="",X9=0),"-",IF(OR(Y9="G",Y9="D"),IF(Y9="G","G","D"),COUNTIF($X$6:$X$45,">"&X9)+1))
A10: 5 | I10: =IF(OR(J10="G",J10="D"),0,IF(AND(F10="",G10=""),0,MAX(0,IFERROR(F10+0,0)+IFERROR(G10+0,0)-IFERROR(H10+0,0)))) | N10: =IF(OR(O10="G",O10="D"),0,IF(AND(K10="",L10=""),0,MAX(0,IFERROR(K10+0,0)+IFERROR(L10+0,0)-IFERROR(M10+0,0)))) | S10: =IF(OR(T10="G",T10="D"),0,IF(AND(P10="",Q10=""),0,MAX(0,IFERROR(P10+0,0)+IFERROR(Q10+0,0)-IFERROR(R10+0,0)))) | X10: =IF(OR(Y10="G",Y10="D"),0,IF(AND(U10="",V10=""),0,MAX(0,IFERROR(U10+0,0)+IFERROR(V10+0,0)-IFERROR(W10+0,0)))) | Z10: =IF(B10="","",IF(OR(J10="G",J10="D"),0,I10)+IF(OR(O10="G",O10="D"),0,N10)+IF(OR(T10="G",T10="D"),0,S10)+IF(OR(Y10="G",Y10="D"),0,X10)) | AA10: =IF(OR(B10="",Z10=0),"-",RANK.EQ(Z10,$Z$6:$Z$45,0)) | AB10: =IF(OR(B10="",I10=0),"-",IF(OR(J10="G",J10="D"),IF(J10="G","G","D"),COUNTIF($I$6:$I$45,">"&I10)+1)) | AC10: =IF(OR(B10="",N10=0),"-",IF(OR(O10="G",O10="D"),IF(O10="G","G","D"),COUNTIF($N$6:$N$45,">"&N10)+1)) | AD10: =IF(OR(B10="",S10=0),"-",IF(OR(T10="G",T10="D"),IF(T10="G","G","D"),COUNTIF($S$6:$S$45,">"&S10)+1)) | AE10: =IF(OR(B10="",X10=0),"-",IF(OR(Y10="G",Y10="D"),IF(Y10="G","G","D"),COUNTIF($X$6:$X$45,">"&X10)+1))
A11: 6 | I11: =IF(OR(J11="G",J11="D"),0,IF(AND(F11="",G11=""),0,MAX(0,IFERROR(F11+0,0)+IFERROR(G11+0,0)-IFERROR(H11+0,0)))) | N11: =IF(OR(O11="G",O11="D"),0,IF(AND(K11="",L11=""),0,MAX(0,IFERROR(K11+0,0)+IFERROR(L11+0,0)-IFERROR(M11+0,0)))) | S11: =IF(OR(T11="G",T11="D"),0,IF(AND(P11="",Q11=""),0,MAX(0,IFERROR(P11+0,0)+IFERROR(Q11+0,0)-IFERROR(R11+0,0)))) | X11: =IF(OR(Y11="G",Y11="D"),0,IF(AND(U11="",V11=""),0,MAX(0,IFERROR(U11+0,0)+IFERROR(V11+0,0)-IFERROR(W11+0,0)))) | Z11: =IF(B11="","",IF(OR(J11="G",J11="D"),0,I11)+IF(OR(O11="G",O11="D"),0,N11)+IF(OR(T11="G",T11="D"),0,S11)+IF(OR(Y11="G",Y11="D"),0,X11)) | AA11: =IF(OR(B11="",Z11=0),"-",RANK.EQ(Z11,$Z$6:$Z$45,0)) | AB11: =IF(OR(B11="",I11=0),"-",IF(OR(J11="G",J11="D"),IF(J11="G","G","D"),COUNTIF($I$6:$I$45,">"&I11)+1)) | AC11: =IF(OR(B11="",N11=0),"-",IF(OR(O11="G",O11="D"),IF(O11="G","G","D"),COUNTIF($N$6:$N$45,">"&N11)+1)) | AD11: =IF(OR(B11="",S11=0),"-",IF(OR(T11="G",T11="D"),IF(T11="G","G","D"),COUNTIF($S$6:$S$45,">"&S11)+1)) | AE11: =IF(OR(B11="",X11=0),"-",IF(OR(Y11="G",Y11="D"),IF(Y11="G","G","D"),COUNTIF($X$6:$X$45,">"&X11)+1))
A12: 7 | I12: =IF(OR(J12="G",J12="D"),0,IF(AND(F12="",G12=""),0,MAX(0,IFERROR(F12+0,0)+IFERROR(G12+0,0)-IFERROR(H12+0,0)))) | N12: =IF(OR(O12="G",O12="D"),0,IF(AND(K12="",L12=""),0,MAX(0,IFERROR(K12+0,0)+IFERROR(L12+0,0)-IFERROR(M12+0,0)))) | S12: =IF(OR(T12="G",T12="D"),0,IF(AND(P12="",Q12=""),0,MAX(0,IFERROR(P12+0,0)+IFERROR(Q12+0,0)-IFERROR(R12+0,0)))) | X12: =IF(OR(Y12="G",Y12="D"),0,IF(AND(U12="",V12=""),0,MAX(0,IFERROR(U12+0,0)+IFERROR(V12+0,0)-IFERROR(W12+0,0)))) | Z12: =IF(B12="","",IF(OR(J12="G",J12="D"),0,I12)+IF(OR(O12="G",O12="D"),0,N12)+IF(OR(T12="G",T12="D"),0,S12)+IF(OR(Y12="G",Y12="D"),0,X12)) | AA12: =IF(OR(B12="",Z12=0),"-",RANK.EQ(Z12,$Z$6:$Z$45,0)) | AB12: =IF(OR(B12="",I12=0),"-",IF(OR(J12="G",J12="D"),IF(J12="G","G","D"),COUNTIF($I$6:$I$45,">"&I12)+1)) | AC12: =IF(OR(B12="",N12=0),"-",IF(OR(O12="G",O12="D"),IF(O12="G","G","D"),COUNTIF($N$6:$N$45,">"&N12)+1)) | AD12: =IF(OR(B12="",S12=0),"-",IF(OR(T12="G",T12="D"),IF(T12="G","G","D"),COUNTIF($S$6:$S$45,">"&S12)+1)) | AE12: =IF(OR(B12="",X12=0),"-",IF(OR(Y12="G",Y12="D"),IF(Y12="G","G","D"),COUNTIF($X$6:$X$45,">"&X12)+1))
A13: 8 | I13: =IF(OR(J13="G",J13="D"),0,IF(AND(F13="",G13=""),0,MAX(0,IFERROR(F13+0,0)+IFERROR(G13+0,0)-IFERROR(H13+0,0)))) | N13: =IF(OR(O13="G",O13="D"),0,IF(AND(K13="",L13=""),0,MAX(0,IFERROR(K13+0,0)+IFERROR(L13+0,0)-IFERROR(M13+0,0)))) | S13: =IF(OR(T13="G",T13="D"),0,IF(AND(P13="",Q13=""),0,MAX(0,IFERROR(P13+0,0)+IFERROR(Q13+0,0)-IFERROR(R13+0,0)))) | X13: =IF(OR(Y13="G",Y13="D"),0,IF(AND(U13="",V13=""),0,MAX(0,IFERROR(U13+0,0)+IFERROR(V13+0,0)-IFERROR(W13+0,0)))) | Z13: =IF(B13="","",IF(OR(J13="G",J13="D"),0,I13)+IF(OR(O13="G",O13="D"),0,N13)+IF(OR(T13="G",T13="D"),0,S13)+IF(OR(Y13="G",Y13="D"),0,X13)) | AA13: =IF(OR(B13="",Z13=0),"-",RANK.EQ(Z13,$Z$6:$Z$45,0)) | AB13: =IF(OR(B13="",I13=0),"-",IF(OR(J13="G",J13="D"),IF(J13="G","G","D"),COUNTIF($I$6:$I$45,">"&I13)+1)) | AC13: =IF(OR(B13="",N13=0),"-",IF(OR(O13="G",O13="D"),IF(O13="G","G","D"),COUNTIF($N$6:$N$45,">"&N13)+1)) | AD13: =IF(OR(B13="",S13=0),"-",IF(OR(T13="G",T13="D"),IF(T13="G","G","D"),COUNTIF($S$6:$S$45,">"&S13)+1)) | AE13: =IF(OR(B13="",X13=0),"-",IF(OR(Y13="G",Y13="D"),IF(Y13="G","G","D"),COUNTIF($X$6:$X$45,">"&X13)+1))
A14: 9 | I14: =IF(OR(J14="G",J14="D"),0,IF(AND(F14="",G14=""),0,MAX(0,IFERROR(F14+0,0)+IFERROR(G14+0,0)-IFERROR(H14+0,0)))) | N14: =IF(OR(O14="G",O14="D"),0,IF(AND(K14="",L14=""),0,MAX(0,IFERROR(K14+0,0)+IFERROR(L14+0,0)-IFERROR(M14+0,0)))) | S14: =IF(OR(T14="G",T14="D"),0,IF(AND(P14="",Q14=""),0,MAX(0,IFERROR(P14+0,0)+IFERROR(Q14+0,0)-IFERROR(R14+0,0)))) | X14: =IF(OR(Y14="G",Y14="D"),0,IF(AND(U14="",V14=""),0,MAX(0,IFERROR(U14+0,0)+IFERROR(V14+0,0)-IFERROR(W14+0,0)))) | Z14: =IF(B14="","",IF(OR(J14="G",J14="D"),0,I14)+IF(OR(O14="G",O14="D"),0,N14)+IF(OR(T14="G",T14="D"),0,S14)+IF(OR(Y14="G",Y14="D"),0,X14)) | AA14: =IF(OR(B14="",Z14=0),"-",RANK.EQ(Z14,$Z$6:$Z$45,0)) | AB14: =IF(OR(B14="",I14=0),"-",IF(OR(J14="G",J14="D"),IF(J14="G","G","D"),COUNTIF($I$6:$I$45,">"&I14)+1)) | AC14: =IF(OR(B14="",N14=0),"-",IF(OR(O14="G",O14="D"),IF(O14="G","G","D"),COUNTIF($N$6:$N$45,">"&N14)+1)) | AD14: =IF(OR(B14="",S14=0),"-",IF(OR(T14="G",T14="D"),IF(T14="G","G","D"),COUNTIF($S$6:$S$45,">"&S14)+1)) | AE14: =IF(OR(B14="",X14=0),"-",IF(OR(Y14="G",Y14="D"),IF(Y14="G","G","D"),COUNTIF($X$6:$X$45,">"&X14)+1))
